<mujoco model="Lite3">
  <compiler angle="radian"/>

  <default>
    <default class="Lite3">
      <joint armature="0.01" damping="0.51"/>
    </default>
    <default class="visual">
      <geom type="mesh" contype="0" conaffinity="0"/>
    </default>
    <default class="collision">
      <geom group="3"/>
    </default>
    <default class="foot">
      <geom type="sphere" size="0.022" rgba="1 1 1 1" friction="1.0 0.3 0.3" />
    </default>
    <default class="foot_site">
      <site size="0.022" />
    </default>
  </default>

  <asset>
    <mesh name="torso" file="torso.STL"/>
    <mesh name="fr_thigh" file="fr_thigh.STL"/>
    <mesh name="fr_shank" file="fr_shank.STL"/>
    <mesh name="fr_hip" file="fr_hip.STL"/>

    <mesh name="fl_thigh" file="fl_thigh.STL"/>
    <mesh name="fl_shank" file="fl_shank.STL"/>
    <mesh name="fl_hip" file="fl_hip.STL"/>
    
    <mesh name="hl_thigh" file="hl_thigh.STL"/>
    <mesh name="hl_shank" file="hl_shank.STL"/>
    <mesh name="hl_hip" file="hl_hip.STL"/>
    
    <mesh name="hr_thigh" file="hr_thigh.STL"/>
    <mesh name="hr_shank" file="hr_shank.STL"/>
    <mesh name="hr_hip" file="hr_hip.STL"/>
  </asset>

  <worldbody>
    <body name="command_indicator_mocap" pos="0 0 0" mocap="true">
      <geom conaffinity="0" contype="0" pos="0.3 0 0" rgba="0.7 0 0 0.5" size="0.4 0.005 0.005" type="box" group="1"></geom>
      <geom conaffinity="0" contype="0" pos="0 0.3 0" rgba="0 0.7 0 0.5" size="0.005 0.4 0.005" type="box" group="1"></geom>
      <geom conaffinity="0" contype="0" pos="0 0 0.3" rgba="0 0 0.7 0.5" size="0.005 0.005 0.4" type="box" group="1"></geom>
    </body>

    <body name="torso" pos="0 0 0.5" childclass="Lite3">
      <freejoint name="torso" />
      <geom type="mesh" rgba="1 1 1 1" mesh="torso"/>
      <inertial pos="0 0 0" mass="5.6056" diaginertia="0.02456 0.05518 0.07016"/>
      <site name="imu" pos="0 0 0" size="0.01"/>

      <body name="FL_HIP" pos="0.1745 0.062 0">

        <geom type="mesh" mesh="fl_hip" pos="0 0 0" class="visual"/>
        <inertial pos="-0.00601 -0.0066532 0.00034295" quat="0 0.707107 0 0.707107" mass="0.55" diaginertia="0.0004472 0.0004028 0.0003949"/>
        <joint name="FL_HipX_joint" pos="0 0 0" axis="-1 0 0" range="-0.523 0.523" actuatorfrcrange="-30 30"/>
        
        <body name="FL_THIGH" pos="0 0.09735 0">
          
          <geom type="mesh" mesh="fl_thigh" pos="0 0 0" class="visual"/>
          <inertial pos="-0.0052817 -0.014632 -0.042672" mass="0.86" diaginertia="0.005736 0.00496 0.001436"/>
          <joint name="FL_HipY_joint" pos="0 0 0" axis="0 -1 0" range="-2.67 0.314" actuatorfrcrange="-30 30"/>
          <geom size="0.02 0.02 0.16" pos="0 0 -0.08" type="box" rgba="1 1 1 1" class="collision"/>
          
          <body name="FL_SHANK" pos="0 0 -0.2">
            
            <inertial pos="0.00573034 -1.28547e-06 -0.131807" quat="0.707101 0.00359881 0.00359725 0.707095" mass="0.173" diaginertia="0.00104615 0.00102919 3.19053e-05"/>
            <joint name="FL_Knee_joint" pos="0 0 0" axis="0 -1 0" range="0.524 2.792" actuatorfrcrange="-30 30"/>
            
            <geom size="0.01 0.01 0.09" pos="0 0 -0.09" type="box" rgba="1 1 1 1"  class="collision"/>
            <geom type="mesh" mesh="fl_shank" pos="0 0 0" class="visual"/>

            <body name="FL_FOOT" pos="0 0 -0.21012">
              <inertial pos="0 0 0" mass="0.02" diaginertia="0 0 0"/>
              <geom name="FL_FOOT" class="foot"/>
              <site name="FL_site" class="foot_site" />
            </body>

            <geom size="0.022" pos="0 0 -0.21012" quat="0.707107 0.707107 0 0"/>

          </body>
        </body>
      </body>

      <body name="FR_HIP" pos="0.1745 -0.062 0">
      
        <geom type="mesh" mesh="fr_hip" pos="0 0 0" class="visual"/>
        <inertial pos="-0.010579 0.011358 0.00048546" mass="0.55" diaginertia="0.0004472 0.0004028 0.0003949"/>
        <joint name="FR_HipX_joint" pos="0 0 0" axis="-1 0 0" range="-0.523 0.523" actuatorfrcrange="-30 30"/>
        
        <body name="FR_THIGH" pos="0 -0.09735 0">
        
          <geom type="mesh" mesh="fr_thigh" pos="0 0 0" class="visual"/>
          <inertial pos="-0.0039245 0.025256 -0.025146" mass="0.86" diaginertia="0.005736 0.00496 0.001436"/>
          <joint name="FR_HipY_joint" pos="0 0 0" axis="0 -1 0" range="-2.67 0.314" actuatorfrcrange="-30 30"/>
          <geom size="0.02 0.02 0.16" pos="0 0 -0.08" type="box" rgba="1 1 1 1" class="collision"/>
          
          <body name="FR_SHANK" pos="0 0 -0.2">
          
            <geom type="mesh" mesh="fr_shank" pos="0 0 0" class="visual"/>
            <inertial pos="0.00573034 -1.28697e-06 -0.131807" quat="0.707101 0.00359881 0.00359725 0.707095" mass="0.173" diaginertia="0.00104615 0.00102919 3.19053e-05"/>
            <joint name="FR_Knee_joint" pos="0 0 0" axis="0 -1 0" range="0.524 2.792" actuatorfrcrange="-30 30"/>       
            <geom size="0.01 0.01 0.09" pos="0 0 -0.09" type="box" rgba="1 1 1 1" class="collision"/>

            <body name="FR_FOOT" pos="0 0 -0.21012">
              <inertial pos="0 0 0" mass="0.02" diaginertia="0 0 0"/>
              <geom name="FR_FOOT" class="foot"/>
              <site name="FR_site" class="foot_site" />
            </body>
          </body>
        </body>
      </body>
      
      <body name="HL_HIP" pos="-0.1745 0.062 0">
      
        <geom type="mesh" mesh="hl_hip" pos="0 0 0" class="visual"/>
        <inertial pos="0.010905 -0.012636 0.001051" quat="0 0.707107 0 0.707107" mass="0.55" diaginertia="0.0004472 0.0004028 0.0003949"/>
        <joint name="HL_HipX_joint" pos="0 0 0" axis="-1 0 0" range="-0.523 0.523" actuatorfrcrange="-30 30"/>
        
        <body name="HL_THIGH" pos="0 0.09735 0">
        
          <geom type="mesh" mesh="hl_thigh" pos="0 0 0" class="visual"/>
          <inertial pos="-0.0057137 -0.014631 -0.042453" mass="0.86" diaginertia="0.005736 0.00496 0.001436"/>
          <joint name="HL_HipY_joint" pos="0 0 0" axis="0 -1 0" range="-2.67 0.314" actuatorfrcrange="-30 30"/>
          <geom size="0.02 0.02 0.16" pos="0 0 -0.08" type="box" rgba="1 1 1 1" class="collision"/>
          
          <body name="HL_SHANK" pos="0 0 -0.2">

            <geom type="mesh" mesh="hl_shank" pos="0 0 0" class="visual"/>
            <inertial pos="0.00573034 -1.2875e-06 -0.131807" quat="0.707101 0.00359881 0.00359725 0.707095" mass="0.173" diaginertia="0.00104615 0.00102919 3.19053e-05"/>
            <joint name="HL_Knee_joint" pos="0 0 0" axis="0 -1 0" range="0.524 2.792" actuatorfrcrange="-30 30"/>
            
            <geom size="0.01 0.01 0.09" pos="0 0 -0.09" type="box" rgba="1 1 1 1" class="collision"/>
            <geom size="0.022" pos="0 0 -0.21012" quat="0.707107 0.707107 0 0"/>

            <body name="HL_FOOT" pos="0 0 -0.21012">
              <inertial pos="0 0 0" mass="0.02" diaginertia="0 0 0"/>
              <geom name="HL_FOOT" class="foot"/>
              <site name="HL_site" class="foot_site" />
            </body>

          </body>
        </body>
      </body>
      
      <body name="HR_HIP" pos="-0.1745 -0.062 0">
      
        <geom type="mesh" mesh="hr_hip" pos="0 0 0" class="visual"/>
        <inertial pos="0.010354 0.011423 0.00049498" quat="0 0.707107 0 0.707107" mass="0.55" diaginertia="0.0004472 0.0004028 0.0003949"/>
        <joint name="HR_HipX_joint" pos="0 0 0" axis="-1 0 0" range="-0.523 0.523" actuatorfrcrange="-30 30"/>
        
        <body name="HR_THIGH" pos="0 -0.09735 0">
        
          <geom type="mesh" mesh="hr_thigh" pos="0 0 0" class="visual"/>
          <inertial pos="-0.0031903 0.02526 -0.025617" mass="0.86" diaginertia="0.005736 0.00496 0.001436"/>
          <joint name="HR_HipY_joint" pos="0 0 0" axis="0 -1 0" range="-2.67 0.314" actuatorfrcrange="-30 30"/>
          <geom size="0.02 0.02 0.16" pos="0 0 -0.08" type="box" rgba="1 1 1 1" class="collision"/>
          
          <body name="HR_SHANK" pos="0 0 -0.2">
          
            <geom type="mesh" mesh="hr_shank" pos="0 0 0" class="visual"/>
            <inertial pos="0.00573034 -1.28493e-06 -0.131807" quat="0.707101 0.00359881 0.00359725 0.707095" mass="0.173" diaginertia="0.00104615 0.00102919 3.19053e-05"/>
            <joint name="HR_Knee_joint" pos="0 0 0" axis="0 -1 0" range="0.524 2.792" actuatorfrcrange="-30 30"/>
            
            <geom size="0.01 0.01 0.09" pos="0 0 -0.09" type="box" rgba="1 1 1 1" class="collision"/>
            <geom size="0.022" pos="0 0 -0.21012" quat="0.707107 0.707107 0 0"/>

            <body name="HR_FOOT" pos="0 0 -0.21012">
              <inertial pos="0 0 0" mass="0.02" diaginertia="0 0 0"/>
              <geom name="HR_FOOT" class="foot"/>
              <site name="HR_site" class="foot_site" />
            </body>

          </body>
        </body>
      </body>
    </body>
  </worldbody>

  <actuator>
    <!-- Front Left Leg -->
    <position joint="FL_HipX_joint" name="FL_HipX_actuator" kp="20" kv="0.7" ctrlrange="-0.523 0.523"/>
    <position joint="FL_HipY_joint" name="FL_HipY_actuator" kp="20" kv="0.7" ctrlrange="-2.67 0.314"/>
    <position joint="FL_Knee_joint" name="FL_Knee_actuator" kp="20" kv="0.7" ctrlrange="0.524 2.792"/>
    
    <!-- Front Right Leg -->
    <position joint="FR_HipX_joint" name="FR_HipX_actuator" kp="20" kv="0.7" ctrlrange="-0.523 0.523"/>
    <position joint="FR_HipY_joint" name="FR_HipY_actuator" kp="20" kv="0.7" ctrlrange="-2.67 0.314"/>
    <position joint="FR_Knee_joint" name="FR_Knee_actuator" kp="20" kv="0.7" ctrlrange="0.524 2.792"/>
    
    <!-- Hind Left Leg -->
    <position joint="HL_HipX_joint" name="HL_HipX_actuator" kp="20" kv="0.7" ctrlrange="-0.523 0.523"/>
    <position joint="HL_HipY_joint" name="HL_HipY_actuator" kp="20" kv="0.7" ctrlrange="-2.67 0.314"/>
    <position joint="HL_Knee_joint" name="HL_Knee_actuator" kp="20" kv="0.7" ctrlrange="0.524 2.792"/>
    
    <!-- Hind Right Leg -->
    <position joint="HR_HipX_joint" name="HR_HipX_actuator" kp="20" kv="0.7" ctrlrange="-0.523 0.523"/>
    <position joint="HR_HipY_joint" name="HR_HipY_actuator" kp="20" kv="0.7" ctrlrange="-2.67 0.314"/>
    <position joint="HR_Knee_joint" name="HR_Knee_actuator" kp="20" kv="0.7" ctrlrange="0.524 2.792"/>
  </actuator>

  <sensor>
    <framequat name="imu_quat" objtype="site" objname="imu"/>

    <touch name="FL_touch" site="FL_site"/>
    <touch name="FR_touch" site="FR_site"/>
    <touch name="HL_touch" site="HL_site"/>
    <touch name="HR_touch" site="HR_site"/>
  </sensor>
</mujoco>
