<mujoco model="go2">
  <compiler angle="radian" meshdir="assets" autolimits="true"/>

  <option cone="elliptic" impratio="100"/>
  <option integrator="implicitfast"/>
  <default>
    <default class="go2">
      <geom friction="0.6" margin="0.001" condim="1"/>
      <joint axis="0 1 0" damping="0.5" armature="0.01"/>
      <position kp="45" dampratio="1" inheritrange="1"/>
      <!-- <motor ctrlrange="-23.7 23.7"/> -->
      <default class="abduction">
        <joint axis="1 0 0" range="-1.0472 1.0472"/>
      </default>
      <default class="hip">
        <default class="front_hip">
          <joint range="-1.5708 3.4907"/>
        </default>
        <default class="back_hip">
          <joint range="-0.5236 4.5379"/>
        </default>
      </default>
      <default class="knee">
        <joint range="-2.7227 -0.83776"/>
        <!-- <motor ctrlrange="-45.43 45.43"/> -->
      </default>
      <default class="visual">
        <geom type="mesh" contype="0" conaffinity="0" group="2"/>
      </default>
      <default class="collision">
        <geom group="3"/>
        <default class="foot">
          <!-- <geom size="0.023" pos="-0.002 0 -0.213" priority="1" solimp="0.015 1 0.022" condim="6"
            friction="1.0 0.2 0.01"/> -->
          <geom type="sphere" size="0.03" friction="1 0.005 0.0001" pos="-0.002 0 -0.213" priority="1"
               solref="0.02 1" solimp="0.9 0.4 0.01" margin="0.01" gap="0.001"/>
        </default>
        <default class="foot_site">
          <site size="0.05" pos="-0.002 0 -0.213" group="3"/>
        </default>
      </default>
    </default>
  </default>

  <asset>
    <material name="metal" rgba=".9 .95 .95 1"/>
    <material name="black" rgba="0 0 0 1"/>
    <material name="white" rgba="1 1 1 1"/>
    <material name="gray" rgba="0.671705 0.692426 0.774270 1"/>

    <texture type="2d" name="Metal009_color"      file="../../../textures/Metal009_2K-PNG/Metal009_2K-PNG_Color.png"/>
    <texture type="2d" name="Metal009_roughness"  file="../../../textures/Metal009_2K-PNG/Metal009_2K-PNG_Roughness.png"/>
    <texture type="2d" name="Metal009_metalic"  file="../../../textures/Metal009_2K-PNG/Metal009_2K-PNG_Metalness.png"/>
    <texture type="2d" name="Metal009_normal"     file="../../../textures/Metal009_2K-PNG/Metal009_2K-PNG_NormalDX.png"/>

    <material name="pbr_metal_gray">
      <layer role="rgb"        texture="Metal009_color"/>
      <layer role="normal"     texture="Metal009_normal"/>
      <layer role="roughness"  texture="Metal009_roughness"/>
      <layer role="metallic"  texture="Metal009_metalic"/>
    </material>

    <texture type="2d" name="Metal044A_color"      file="../../../textures/Metal044A_2K-PNG/Metal044A_2K-PNG_Color.png"/>
    <texture type="2d" name="Metal044A_roughness"  file="../../../textures/Metal044A_2K-PNG/Metal044A_2K-PNG_Roughness.png"/>
    <texture type="2d" name="Metal044A_metalic"  file="../../../textures/Metal044A_2K-PNG/Metal044A_2K-PNG_Metalness.png"/>
    <texture type="2d" name="Metal044A_normal"     file="../../../textures/Metal044A_2K-PNG/Metal044A_2K-PNG_NormalDX.png"/>

    <material name="pbr_metal_silver_smooth">
      <layer role="rgb"        texture="Metal044A_color"/>
      <layer role="normal"     texture="Metal044A_normal"/>
      <layer role="roughness"  texture="Metal044A_roughness"/>
      <layer role="metallic"  texture="Metal044A_metalic"/>
    </material>

    <texture type="2d" name="Metal044B_color"      file="../../../textures/Metal044B_2K-PNG/Metal044B_2K-PNG_Color.png"/>
    <texture type="2d" name="Metal044B_roughness"  file="../../../textures/Metal044B_2K-PNG/Metal044B_2K-PNG_Roughness.png"/>
    <texture type="2d" name="Metal044B_metalic"  file="../../../textures/Metal044B_2K-PNG/Metal044B_2K-PNG_Metalness.png"/>
    <texture type="2d" name="Metal044B_normal"     file="../../../textures/Metal044B_2K-PNG/Metal044B_2K-PNG_NormalDX.png"/>

    <material name="pbr_metal_silver_rough">
      <layer role="rgb"        texture="Metal044B_color"/>
      <layer role="normal"     texture="Metal044B_normal"/>
      <layer role="roughness"  texture="Metal044B_roughness"/>
      <layer role="metallic"  texture="Metal044B_metalic"/>
    </material>    

    <texture type="2d" name="Plastic006_color"      file="../../../textures/Plastic006_2K-PNG/Plastic006_2K-PNG_Color.png"/>
    <texture type="2d" name="Plastic006_roughness"  file="../../../textures/Plastic006_2K-PNG/Plastic006_2K-PNG_Roughness.png"/>
    <texture type="2d" name="Plastic006_normal"     file="../../../textures/Plastic006_2K-PNG/Plastic006_2K-PNG_NormalDX.png"/>

    <material name="pbr_plastic_black" metallic ="0.05">
      <layer role="rgb"        texture="Plastic006_color"/>
      <layer role="normal"     texture="Plastic006_normal"/>
      <layer role="roughness"  texture="Plastic006_roughness"/>
    </material>

    <texture type="2d" name="Plastic013A_color"      file="../../../textures/Plastic013A_2K-PNG/Plastic013A_2K-PNG_Color.png"/>
    <texture type="2d" name="Plastic013A_roughness"  file="../../../textures/Plastic013A_2K-PNG/Plastic013A_2K-PNG_Roughness.png"/>
    <texture type="2d" name="Plastic013A_normal"     file="../../../textures/Plastic013A_2K-PNG/Plastic013A_2K-PNG_NormalDX.png"/>

    <material name="pbr_plastic_white" metallic ="0.05">
      <layer role="rgb"        texture="Plastic013A_color"/>
      <layer role="normal"     texture="Plastic013A_normal"/>
      <layer role="roughness"  texture="Plastic013A_roughness"/>
    </material>

    <texture type="2d" name="Plastic010_color"      file="../../../textures/Plastic010_2K-PNG/Plastic010_2K-PNG_Color.png"/>
    <texture type="2d" name="Plastic010_roughness"  file="../../../textures/Plastic010_2K-PNG/Plastic010_2K-PNG_Roughness.png"/>
    <texture type="2d" name="Plastic010_normal"     file="../../../textures/Plastic010_2K-PNG/Plastic010_2K-PNG_NormalDX.png"/>

    <material name="pbr_plastic_gray" metallic ="0.05">
      <layer role="rgb"        texture="Plastic010_color"/>
      <layer role="normal"     texture="Plastic010_normal"/>
      <layer role="roughness"  texture="Plastic010_roughness"/>      
    </material>

    <mesh file="base_0.obj"/>
    <mesh file="base_1.obj"/>
    <mesh file="base_2.obj"/>
    <mesh file="base_3.obj"/>
    <mesh file="base_4.obj"/>
    <mesh file="hip_0.obj"/>
    <mesh file="hip_1.obj"/>
    <mesh file="thigh_0.obj"/>
    <mesh file="thigh_1.obj"/>
    <mesh file="thigh_mirror_0.obj"/>
    <mesh file="thigh_mirror_1.obj"/>
    <mesh file="calf_0.obj"/>
    <mesh file="calf_1.obj"/>
    <mesh file="calf_mirror_0.obj"/>
    <mesh file="calf_mirror_1.obj"/>
    <mesh file="foot.obj"/>
  </asset>

  <worldbody>
    <body name="command_indicator_mocap" pos="0 0 0" mocap="true">
      <geom conaffinity="0" contype="0" pos="0.1 0 0" rgba="0.7 0 0 0.5" size="0.1 0.005 0.005" type="box" group="1"></geom>
      <geom conaffinity="0" contype="0" pos="0 0.1 0" rgba="0 0.7 0 0.5" size="0.005 0.1 0.005" type="box" group="1"></geom>
      <geom conaffinity="0" contype="0" pos="0 0 0.1" rgba="0 0 0.7 0.5" size="0.005 0.005 0.1" type="box" group="1"></geom>
    </body>
    <!-- <body mocap="true" name="mocap" pos="0. 0. 0.78"> -->
      <!-- <site pos="0 0 0.075" size="0.003 0.003 0.1" type="box" name="mocap_left_site1" rgba="0 0 1 1"/> -->
      <!-- <site pos="0 0.075 0" size="0.003 0.1 0.003" type="box" name="mocap_left_site2" rgba="0 1 0 1"/> -->
      <!-- <site pos="0.075 0 0" size="0.1 0.003 0.003" type="box" name="mocap_left_site3" rgba="1 0 0 1"/> -->
    <!-- </body> -->

    <body name="base" pos="0 0 0.445" childclass="go2">
      <inertial pos="0.021112 0 -0.005366" quat="-0.000543471 0.713435 -0.00173769 0.700719" mass="6.921"
        diaginertia="0.107027 0.0980771 0.0244531"/>
      <freejoint name="base"/>
      <geom mesh="base_0" material="pbr_plastic_black" class="visual"/>
      <geom mesh="base_1" material="pbr_plastic_black" class="visual"/>
      <geom mesh="base_2" material="pbr_plastic_black" class="visual"/>
      <geom mesh="base_3" material="pbr_plastic_white" class="visual"/>
      <geom mesh="base_4" material="pbr_plastic_gray" class="visual"/>
      <geom size="0.1881 0.04675 0.06" type="box" class="collision"/>
      <geom size="0.05 0.045" pos="0.285 0 0.01" type="cylinder" class="collision"/>
      <geom size="0.047" pos="0.293 0 -0.06" class="collision"/>
      <site name="imu" pos="-0.02557 0 0.04232"/>
      <body name="FL_hip" pos="0.1934 0.0465 0">
        <inertial pos="-0.0054 0.00194 -0.000105" quat="0.497014 0.499245 0.505462 0.498237" mass="0.678"
          diaginertia="0.00088403 0.000596003 0.000479967"/>
        <joint name="FL_hip_joint" class="abduction"/>
        <geom mesh="hip_0" material="pbr_metal_gray" class="visual"/>
        <geom mesh="hip_1" material="pbr_plastic_gray" class="visual"/>
        <geom size="0.046 0.02" pos="0 0.08 0" quat="1 1 0 0" type="cylinder" class="collision"/>
        <body name="FL_thigh" pos="0 0.0955 0">
          <inertial pos="-0.00374 -0.0223 -0.0327" quat="0.829533 0.0847635 -0.0200632 0.551623" mass="1.152"
            diaginertia="0.00594973 0.00584149 0.000878787"/>
          <joint name="FL_thigh_joint" class="front_hip"/>
          <geom mesh="thigh_0" material="pbr_metal_silver_rough" class="visual"/>
          <geom mesh="thigh_1" material="pbr_plastic_gray" class="visual"/>
          <geom size="0.1065 0.01225 0.017" pos="0 0 -0.1065" quat="0.707107 0 0.707107 0" type="box" class="collision"/>
          <body name="FL_calf" pos="0 0 -0.213">
            <inertial pos="0.00629595 -0.000622121 -0.141417" quat="0.710672 0.00154099 -0.00450087 0.703508"
              mass="0.241352" diaginertia="0.0014901 0.00146356 5.31397e-05"/>
            <joint name="FL_calf_joint" class="knee"/>
            <geom mesh="calf_0" material="pbr_plastic_gray" class="visual"/>
            <geom mesh="calf_1" material="pbr_plastic_black" class="visual"/>
            <geom size="0.012 0.06" pos="0.008 0 -0.06" quat="0.994493 0 -0.104807 0" type="cylinder" class="collision"/>
            <geom size="0.011 0.0325" pos="0.02 0 -0.148" quat="0.999688 0 0.0249974 0" type="cylinder" class="collision"/>
            <geom pos="0 0 -0.213" mesh="foot" class="visual" material="pbr_plastic_black"/>
            <body name="FL_foot">
              <geom name="FL" class="foot"/>
              <site name="FL_site" class="foot_site" />
            </body>
          </body>
        </body>
      </body>
      <body name="FR_hip" pos="0.1934 -0.0465 0">
        <inertial pos="-0.0054 -0.00194 -0.000105" quat="0.498237 0.505462 0.499245 0.497014" mass="0.678"
          diaginertia="0.00088403 0.000596003 0.000479967"/>
        <joint name="FR_hip_joint" class="abduction"/>
        <geom mesh="hip_0" material="pbr_metal_gray" class="visual" quat="4.63268e-05 1 0 0"/>
        <geom mesh="hip_1" material="pbr_plastic_gray" class="visual" quat="4.63268e-05 1 0 0"/>
        <geom size="0.046 0.02" pos="0 -0.08 0" quat="0.707107 0.707107 0 0" type="cylinder" class="collision"/>
        <body name="FR_thigh" pos="0 -0.0955 0">
          <inertial pos="-0.00374 0.0223 -0.0327" quat="0.551623 -0.0200632 0.0847635 0.829533" mass="1.152"
            diaginertia="0.00594973 0.00584149 0.000878787"/>
          <joint name="FR_thigh_joint" class="front_hip"/>
          <geom mesh="thigh_mirror_0" material="pbr_metal_silver_rough" class="visual"/>
          <geom mesh="thigh_mirror_1" material="pbr_plastic_gray" class="visual"/>
          <geom size="0.1065 0.01225 0.017" pos="0 0 -0.1065" quat="0.707107 0 0.707107 0" type="box" class="collision"/>
          <body name="FR_calf" pos="0 0 -0.213">
            <inertial pos="0.00629595 0.000622121 -0.141417" quat="0.703508 -0.00450087 0.00154099 0.710672"
              mass="0.241352" diaginertia="0.0014901 0.00146356 5.31397e-05"/>
            <joint name="FR_calf_joint" class="knee"/>
            <geom mesh="calf_mirror_0" material="pbr_plastic_gray" class="visual"/>
            <geom mesh="calf_mirror_1" material="pbr_plastic_black" class="visual"/>
            <geom size="0.013 0.06" pos="0.01 0 -0.06" quat="0.995004 0 -0.0998334 0" type="cylinder" class="collision"/>
            <geom size="0.011 0.0325" pos="0.02 0 -0.148" quat="0.999688 0 0.0249974 0" type="cylinder" class="collision"/>
            <geom pos="0 0 -0.213" mesh="foot" class="visual" material="pbr_plastic_black"/>
            <body name="FR_foot">
              <geom name="FR" class="foot"/>
              <site name="FR_site" class="foot_site" />
            </body>
          </body>
        </body>
      </body>
      <body name="RL_hip" pos="-0.1934 0.0465 0">
        <inertial pos="0.0054 0.00194 -0.000105" quat="0.505462 0.498237 0.497014 0.499245" mass="0.678"
          diaginertia="0.00088403 0.000596003 0.000479967"/>
        <joint name="RL_hip_joint" class="abduction"/>
        <geom mesh="hip_0" material="pbr_metal_gray" class="visual" quat="4.63268e-05 0 1 0"/>
        <geom mesh="hip_1" material="pbr_plastic_gray" class="visual" quat="4.63268e-05 0 1 0"/>
        <geom size="0.046 0.02" pos="0 0.08 0" quat="0.707107 0.707107 0 0" type="cylinder" class="collision"/>
        <body name="RL_thigh" pos="0 0.0955 0">
          <inertial pos="-0.00374 -0.0223 -0.0327" quat="0.829533 0.0847635 -0.0200632 0.551623" mass="1.152"
            diaginertia="0.00594973 0.00584149 0.000878787"/>
          <joint name="RL_thigh_joint" class="back_hip"/>
          <geom mesh="thigh_0" material="pbr_metal_silver_rough" class="visual"/>
          <geom mesh="thigh_1" material="pbr_plastic_gray" class="visual"/>
          <geom size="0.1065 0.01225 0.017" pos="0 0 -0.1065" quat="0.707107 0 0.707107 0" type="box" class="collision"/>
          <body name="RL_calf" pos="0 0 -0.213">
            <inertial pos="0.00629595 -0.000622121 -0.141417" quat="0.710672 0.00154099 -0.00450087 0.703508"
              mass="0.241352" diaginertia="0.0014901 0.00146356 5.31397e-05"/>
            <joint name="RL_calf_joint" class="knee"/>
            <geom mesh="calf_0" material="pbr_plastic_gray" class="visual"/>
            <geom mesh="calf_1" material="pbr_plastic_black" class="visual"/>
            <geom size="0.013 0.06" pos="0.01 0 -0.06" quat="0.995004 0 -0.0998334 0" type="cylinder" class="collision"/>
            <geom size="0.011 0.0325" pos="0.02 0 -0.148" quat="0.999688 0 0.0249974 0" type="cylinder" class="collision"/>
            <geom pos="0 0 -0.213" mesh="foot" class="visual" material="pbr_plastic_black"/>
            <body name="RL_foot">
              <geom name="RL" class="foot"/>
              <site name="RL_site" class="foot_site" />
            </body>
          </body>
        </body>
      </body>
      <body name="RR_hip" pos="-0.1934 -0.0465 0">
        <inertial pos="0.0054 -0.00194 -0.000105" quat="0.499245 0.497014 0.498237 0.505462" mass="0.678"
          diaginertia="0.00088403 0.000596003 0.000479967"/>
        <joint name="RR_hip_joint" class="abduction"/>
        <geom mesh="hip_0" material="pbr_metal_gray" class="visual" quat="2.14617e-09 4.63268e-05 4.63268e-05 -1"/>
        <geom mesh="hip_1" material="pbr_plastic_gray" class="visual" quat="2.14617e-09 4.63268e-05 4.63268e-05 -1"/>
        <geom size="0.046 0.02" pos="0 -0.08 0" quat="0.707107 0.707107 0 0" type="cylinder" class="collision"/>
        <body name="RR_thigh" pos="0 -0.0955 0">
          <inertial pos="-0.00374 0.0223 -0.0327" quat="0.551623 -0.0200632 0.0847635 0.829533" mass="1.152"
            diaginertia="0.00594973 0.00584149 0.000878787"/>
          <joint name="RR_thigh_joint" class="back_hip"/>
          <geom mesh="thigh_mirror_0" material="pbr_metal_silver_rough" class="visual"/>
          <geom mesh="thigh_mirror_1" material="pbr_plastic_gray" class="visual"/>
          <geom size="0.1065 0.01225 0.017" pos="0 0 -0.1065" quat="0.707107 0 0.707107 0" type="box" class="collision"/>
          <body name="RR_calf" pos="0 0 -0.213">
            <inertial pos="0.00629595 0.000622121 -0.141417" quat="0.703508 -0.00450087 0.00154099 0.710672"
              mass="0.241352" diaginertia="0.0014901 0.00146356 5.31397e-05"/>
            <joint name="RR_calf_joint" class="knee"/>
            <geom mesh="calf_mirror_0" material="pbr_plastic_gray" class="visual"/>
            <geom mesh="calf_mirror_1" material="pbr_plastic_black" class="visual"/>
            <geom size="0.013 0.06" pos="0.01 0 -0.06" quat="0.995004 0 -0.0998334 0" type="cylinder" class="collision"/>
            <geom size="0.011 0.0325" pos="0.02 0 -0.148" quat="0.999688 0 0.0249974 0" type="cylinder" class="collision"/>
            <geom pos="0 0 -0.213" mesh="foot" class="visual" material="pbr_plastic_black"/>
            <body name="RR_foot">
              <geom name="RR" class="foot"/>
              <site name="RR_site" class="foot_site" />
            </body>
          </body>
        </body>
      </body>
    </body>
  </worldbody>

  <!-- <actuator>
    <motor class="abduction" name="FR_hip_actuator" joint="FR_hip_joint"/>
    <motor class="hip" name="FR_thigh_actuator" joint="FR_thigh_joint"/>
    <motor class="knee" name="FR_calf_actuator" joint="FR_calf_joint"/>
    <motor class="abduction" name="FL_hip_actuator" joint="FL_hip_joint"/>
    <motor class="hip" name="FL_thigh_actuator" joint="FL_thigh_joint"/>
    <motor class="knee" name="FL_calf_actuator" joint="FL_calf_joint"/>
    <motor class="abduction" name="RR_hip_actuator" joint="RR_hip_joint"/>
    <motor class="hip" name="RR_thigh_actuator" joint="RR_thigh_joint"/>
    <motor class="knee" name="RR_calf_actuator" joint="RR_calf_joint"/>
    <motor class="abduction" name="RL_hip_actuator" joint="RL_hip_joint"/>
    <motor class="hip" name="RL_thigh_actuator" joint="RL_thigh_joint"/>
    <motor class="knee" name="RL_calf_actuator" joint="RL_calf_joint"/>
  </actuator> -->


  <actuator>
    <!-- 前左腿 -->
    <position name="FL_hip_actuator" joint="FL_hip_joint" class="go2" 
              forcelimited="true" forcerange="-23.7 23.7"/>
    <position name="FL_thigh_actuator" joint="FL_thigh_joint" class="go2" 
              forcelimited="true" forcerange="-23.7 23.7"/>
    <position name="FL_calf_actuator" joint="FL_calf_joint" class="go2"
              forcelimited="true" forcerange="-45.43 45.43"/>

    <!-- 前右腿 -->
    <position name="FR_hip_actuator" joint="FR_hip_joint" class="go2"
              forcelimited="true" forcerange="-23.7 23.7"/>
    <position name="FR_thigh_actuator" joint="FR_thigh_joint" class="go2"
              forcelimited="true" forcerange="-23.7 23.7"/>
    <position name="FR_calf_actuator" joint="FR_calf_joint" class="go2"
              forcelimited="true" forcerange="-45.43 45.43"/>

    <!-- 后左腿 -->
    <position name="RL_hip_actuator" joint="RL_hip_joint" class="go2"
              forcelimited="true" forcerange="-23.7 23.7"/>
    <position name="RL_thigh_actuator" joint="RL_thigh_joint" class="go2"
              forcelimited="true" forcerange="-23.7 23.7"/>
    <position name="RL_calf_actuator" joint="RL_calf_joint" class="go2"
              forcelimited="true" forcerange="-45.43 45.43"/>

    <!-- 后右腿 -->
    <position name="RR_hip_actuator" joint="RR_hip_joint" class="go2"
              forcelimited="true" forcerange="-23.7 23.7"/>
    <position name="RR_thigh_actuator" joint="RR_thigh_joint" class="go2"
              forcelimited="true" forcerange="-23.7 23.7"/>
    <position name="RR_calf_actuator" joint="RR_calf_joint" class="go2"
              forcelimited="true" forcerange="-45.43 45.43"/>
  </actuator>


  <sensor>
    <framequat name="imu_quat" objtype="site" objname="imu"/>
    <gyro name="imu_omega" site="imu" noise="5e-4" cutoff="34.9"/>
    <accelerometer name="imu_acc" site="imu" noise="1e-2" cutoff="157"/>
    <touch name="FL_touch" site="FL_site"/>
    <touch name="FR_touch" site="FR_site"/>
    <touch name="RL_touch" site="RL_site"/>
    <touch name="RR_touch" site="RR_site"/>
  </sensor>

  <!-- <keyframe>
    <key name="home" qpos="0 0 0.27 1 0 0 0 0 0.9 -1.8 0 0.9 -1.8 0 0.9 -1.8 0 0.9 -1.8"
      ctrl="0 0.9 -1.8 0 0.9 -1.8 0 0.9 -1.8 0 0.9 -1.8"/>
  </keyframe> -->
</mujoco>
