<mujoco>
    <option gravity="0.000000000 0.000000000 -9.810000420" timestep="0.0049999999" integrator="implicitfast" density="1.225" viscosity="1.8000001e-05" noslip_iterations="10" iterations="100" sdf_iterations="50">
        <flag multiccd="disable"/>
    </option>
    <size memory="1000M"/>
    <compiler coordinate="local"/>
    <worldbody>
        <light cutoff="30" pos="0 1 1" dir="0 -1 -2"/>
        <light cutoff="30" pos="0 -1 1" dir="0 1 -2"/>
        <body pos="-4.455995083 0.348160446 1.533870339" euler="0.000000000 0.000000000 0.000000000" name="openloong_gripper_2f85_fix_base_usda_fridge_left_up">
            <geom contype="1" conaffinity="1" density="1000" type="box" material="" rgba="0.500000000 0.500000000 0.500000000 1.000000000" solimp="0.899999976 0.949999988 0.001000000" friction="1.000000000 0.005000000 0.000100000" solref="0.020000000 1.000000000" margin="0" condim="3" group="0" pos="0.034918308 0.246351242 -0.000000358" quat="1.000000000 0.000000000 0.000000000 0.000013381" size="0.052000001 0.243000001 0.625000000" name="openloong_gripper_2f85_fix_base_usda_Fridge_02_a_7FE78A4A_FAE9_40AB_9CA8_2E5715AE96F2"/>
            <geom contype="1" conaffinity="1" density="1000" type="box" material="" rgba="0.500000000 0.500000000 0.500000000 1.000000000" solimp="0.899999976 0.949999988 0.001000000" friction="1.000000000 0.005000000 0.000100000" solref="0.020000000 1.000000000" margin="0" condim="3" group="0" pos="-0.055340290 0.240164995 -0.197626591" quat="0.999999940 0.000000000 0.000000000 0.000271916" size="0.035000000 0.200000003 0.075999998" name="openloong_gripper_2f85_fix_base_usda_Fridge_02_g_0C31F56D_6870_4487_8AAF_AAC0ADC85DD3"/>
            <geom contype="1" conaffinity="1" density="1000" type="box" material="" rgba="0.500000000 0.500000000 0.500000000 1.000000000" solimp="0.899999976 0.949999988 0.001000000" friction="1.000000000 0.005000000 0.000100000" solref="0.020000000 1.000000000" margin="0" condim="3" group="0" pos="-0.036716461 0.240169704 0.099823833" quat="1.000000000 0.000000000 0.000000000 0.000120342" size="0.020000000 0.200000003 0.070000000" name="openloong_gripper_2f85_fix_base_usda_Fridge_02_f_65AE5106_7AD8_4AD5_864A_1CB91038AE9C"/>
            <geom contype="1" conaffinity="1" density="1000" type="box" material="" rgba="0.500000000 0.500000000 0.500000000 1.000000000" solimp="0.899999976 0.949999988 0.001000000" friction="1.000000000 0.005000000 0.000100000" solref="0.020000000 1.000000000" margin="0" condim="3" group="0" pos="0.133846283 0.458910882 0.011316895" quat="1.000000000 0.000000000 0.000000000 0.000000417" size="0.008500000 0.016000001 0.595000029" name="openloong_gripper_2f85_fix_base_usda_Fridge_02_b_B2EEFADF_73FB_446C_BC83_4237AE936021"/>
            <geom contype="1" conaffinity="1" density="1000" type="box" material="" rgba="0.500000000 0.500000000 0.500000000 1.000000000" solimp="0.899999976 0.949999988 0.001000000" friction="1.000000000 0.005000000 0.000100000" solref="0.020000000 1.000000000" margin="0" condim="3" group="0" pos="-0.036197186 0.240169704 0.373237491" quat="1.000000000 0.000000000 0.000000000 0.000087470" size="0.020000000 0.200000003 0.070000000" name="openloong_gripper_2f85_fix_base_usda_Fridge_02_e_51E83983_9C66_4824_AC31_B897B951629A"/>
            <geom contype="1" conaffinity="1" density="1000" type="box" material="" rgba="0.500000000 0.500000000 0.500000000 1.000000000" solimp="0.899999976 0.949999988 0.001000000" friction="1.000000000 0.005000000 0.000100000" solref="0.020000000 1.000000000" margin="0" condim="3" group="0" pos="0.097751617 0.454878092 -0.576283276" quat="1.000000000 0.000000000 0.000000000 0.000000417" size="0.029999999 0.018999999 0.008000000" name="openloong_gripper_2f85_fix_base_usda_Fridge_02_c_B159951F_6DC1_4C99_8953_068D5829C447"/>
            <geom contype="1" conaffinity="1" density="1000" type="box" material="" rgba="0.500000000 0.500000000 0.500000000 1.000000000" solimp="0.899999976 0.949999988 0.001000000" friction="1.000000000 0.005000000 0.000100000" solref="0.020000000 1.000000000" margin="0" condim="3" group="0" pos="0.096112251 0.454878092 0.589555621" quat="1.000000000 0.000000000 0.000000000 0.000000417" size="0.029999999 0.018999999 0.008000000" name="openloong_gripper_2f85_fix_base_usda_Fridge_02_d_3B3D4491_F9A5_40B3_A48B_D78EFFAF5FC6"/>
            <joint armature="0" stiffness="0" damping="5" axis="0.000000 0.000000 -1.000000" limited="true" range="0.000000000 180.000000000" type="hinge" name="openloong_gripper_2f85_fix_base_usda_fridge_left_up_joint"/>
        </body>
        <body pos="-4.456572533 1.328142047 1.533870339" euler="0.000000000 0.000000000 0.000000000" name="openloong_gripper_2f85_fix_base_usda_fridge_right_up">
            <geom contype="1" conaffinity="1" density="1000" type="box" material="" rgba="0.500000000 0.500000000 0.500000000 1.000000000" solimp="0.899999976 0.949999988 0.001000000" friction="1.000000000 0.005000000 0.000100000" solref="0.020000000 1.000000000" margin="0" condim="3" group="0" pos="-0.042358875 -0.244417667 0.003658533" quat="0.999999881 0.000000000 0.000000000 0.000160277" size="0.020000000 0.189999998 0.500000000" name="openloong_gripper_2f85_fix_base_usda_geom_454A7864_BE23_4F68_9D8F_BA1779BE625D"/>
            <geom contype="1" conaffinity="1" density="1000" type="box" material="" rgba="0.500000000 0.500000000 0.500000000 1.000000000" solimp="0.899999976 0.949999988 0.001000000" friction="1.000000000 0.005000000 0.000100000" solref="0.020000000 1.000000000" margin="0" condim="3" group="0" pos="0.134432793 -0.461116314 0.011315942" quat="0.999999940 0.000000075 -0.000000089 0.000017196" size="0.008500000 0.016000001 0.595000029" name="openloong_gripper_2f85_fix_base_usda_geom_58329D24_1D80_4889_9F35_C5B1C42F32F1"/>
            <geom contype="1" conaffinity="1" density="1000" type="box" material="" rgba="0.500000000 0.500000000 0.500000000 1.000000000" solimp="0.899999976 0.949999988 0.001000000" friction="1.000000000 0.005000000 0.000100000" solref="0.020000000 1.000000000" margin="0" condim="3" group="0" pos="0.096698761 -0.456393361 0.589552999" quat="0.999999881 0.000000074 -0.000000089 0.000032246" size="0.029999999 0.018999999 0.008000000" name="openloong_gripper_2f85_fix_base_usda_geom_6AAAF60A_6AF8_48F8_8EB1_E55E6713DFFE"/>
            <geom contype="1" conaffinity="1" density="1000" type="box" material="" rgba="0.500000000 0.500000000 0.500000000 1.000000000" solimp="0.899999976 0.949999988 0.001000000" friction="1.000000000 0.005000000 0.000100000" solref="0.020000000 1.000000000" margin="0" condim="3" group="0" pos="0.098338127 -0.456895828 -0.576284051" quat="0.999999940 0.000000074 -0.000000089 0.000029832" size="0.029999999 0.018999999 0.008000000" name="openloong_gripper_2f85_fix_base_usda_geom_056BF45A_6E42_47CF_AB6E_DBAE4D56194B"/>
            <geom contype="1" conaffinity="1" density="1000" type="box" material="" rgba="0.500000000 0.500000000 0.500000000 1.000000000" solimp="0.899999976 0.949999988 0.001000000" friction="1.000000000 0.005000000 0.000100000" solref="0.020000000 1.000000000" margin="0" condim="3" group="0" pos="0.034286022 -0.245587349 0.000602603" quat="0.999999881 0.000000000 0.000000000 0.000051796" size="0.050999999 0.243000001 0.625000000" name="openloong_gripper_2f85_fix_base_usda_geom_E78ABB06_2DAF_4446_BFDF_5172E1A5921A"/>
            <joint armature="0" stiffness="0" damping="5" axis="0.000000 0.000000 1.000000" limited="true" range="0.000000000 180.000000000" type="hinge" name="openloong_gripper_2f85_fix_base_usda_fridge_right_up_joint"/>
        </body>
        <body pos="0.000000000 0.000000000 0.000000000" euler="0.000000000 0.000000000 0.000000000" name="StaticObjcets_StaticObjcets">
            <geom contype="2" conaffinity="2" density="1000" type="box" material="" rgba="0.500000000 0.500000000 0.500000000 1.000000000" solimp="0.899999976 0.949999988 0.001000000" friction="1.000000000 0.005000000 0.000100000" solref="0.020000000 1.000000000" margin="0" condim="3" group="0" pos="-4.761908531 0.835612714 1.871172667" quat="1.000000000 0.000000000 0.000000000 0.000000000" size="0.250000000 0.439999998 0.005000000" name="StaticObjcets_geom_BB91AFF2_A09B_44C2_A716_D7456F8C9441"/>
            <geom contype="2" conaffinity="2" density="1000" type="box" material="" rgba="0.500000000 0.500000000 0.500000000 1.000000000" solimp="0.899999976 0.949999988 0.001000000" friction="1.000000000 0.005000000 0.000100000" solref="0.020000000 1.000000000" margin="0" condim="3" group="0" pos="-4.769333839 0.386707336 1.535037637" quat="0.707029462 0.707027197 -0.010532650 -0.010532619" size="0.300000012 0.600000024 0.010000000" name="StaticObjcets_geom_95677182_46EB_4198_8D2A_16AE45DB7B21"/>
            <geom contype="2" conaffinity="2" density="1000" type="box" material="" rgba="0.500000000 0.500000000 0.500000000 1.000000000" solimp="0.899999976 0.949999988 0.001000000" friction="1.000000000 0.005000000 0.000100000" solref="0.020000000 1.000000000" margin="0" condim="3" group="0" pos="-4.763467789 0.835180044 1.691508532" quat="1.000000000 0.000000000 0.000000000 0.000000000" size="0.250000000 0.439999998 0.005000000" name="StaticObjcets_geom_13135644_3843_4C60_93D9_88E635BC1F4D"/>
            <geom contype="2" conaffinity="2" density="1000" type="box" material="" rgba="0.500000000 0.500000000 0.500000000 1.000000000" solimp="0.899999976 0.949999988 0.001000000" friction="1.000000000 0.005000000 0.000100000" solref="0.020000000 1.000000000" margin="0" condim="3" group="0" pos="-4.454798698 1.079833508 0.470532238" quat="0.707107067 0.000000000 0.000000000 0.707106471" size="0.239999995 0.079999998 0.430000007" name="StaticObjcets_Fridge_03_217A1578_34F2_40B4_ADE5_4B7D2385D09A"/>
            <geom contype="1" conaffinity="1" density="1000" type="plane" material="" rgba="0.500000000 0.500000000 0.500000000 1.000000000" solimp="0.899999976 0.949999988 0.001000000" friction="1.000000000 0.005000000 0.000100000" solref="0.020000000 1.000000000" margin="0" condim="3" group="0" pos="-0.043989260 0.222946882 0.032030921" quat="1.000000000 0.000000000 0.000000000 0.000000000" size="8.000000000 8.000000000 1.000000000" name="StaticObjcets_geom_DFCD9E97_747D_4C04_8520_77CA21804CF9"/>
            <geom contype="2" conaffinity="2" density="1000" type="box" material="" rgba="0.500000000 0.500000000 0.500000000 1.000000000" solimp="0.899999976 0.949999988 0.001000000" friction="1.000000000 0.005000000 0.000100000" solref="0.020000000 1.000000000" margin="0" condim="3" group="0" pos="-4.771282196 1.281533480 1.516736507" quat="0.707029462 0.707027197 0.010532652 0.010532617" size="0.300000012 0.600000024 0.010000000" name="StaticObjcets_geom_71CF74FF_FC59_45CD_BB68_D2C718B2AD1D"/>
            <geom contype="2" conaffinity="2" density="1000" type="box" material="" rgba="0.500000000 0.500000000 0.500000000 1.000000000" solimp="0.899999976 0.949999988 0.001000000" friction="1.000000000 0.005000000 0.000100000" solref="0.020000000 1.000000000" margin="0" condim="3" group="0" pos="-4.765080929 0.836613894 1.500948071" quat="1.000000000 0.000000000 0.000000000 0.000000000" size="0.250000000 0.439999998 0.005000000" name="StaticObjcets_geom_348F09D8_CE03_435F_9E35_1CD9C973571A"/>
            <geom contype="2" conaffinity="2" density="1000" type="box" material="" rgba="0.500000000 0.500000000 0.500000000 1.000000000" solimp="0.899999976 0.949999988 0.001000000" friction="1.000000000 0.005000000 0.000100000" solref="0.020000000 1.000000000" margin="0" condim="3" group="0" pos="-4.717486858 0.835144579 1.096694350" quat="1.000000000 0.000000000 0.000000000 0.000000000" size="0.200000003 0.439999998 0.119999997" name="StaticObjcets_geom_9979BE85_E241_4DFF_96D1_50365FA3052F"/>
            <geom contype="2" conaffinity="2" density="1000" type="box" material="" rgba="0.500000000 0.500000000 0.500000000 1.000000000" solimp="0.899999976 0.949999988 0.001000000" friction="1.000000000 0.005000000 0.000100000" solref="0.020000000 1.000000000" margin="0" condim="3" group="0" pos="-4.453287601 0.590693057 0.470532209" quat="0.707107067 0.000000000 0.000000000 0.707106471" size="0.239999995 0.079999998 0.430000007" name="StaticObjcets_Fridge_04_a_A7E26F71_7850_475D_90C6_AA81FEA37373"/>
            <geom contype="1" conaffinity="1" density="1000" type="box" material="" rgba="0.500000000 0.500000000 0.500000000 1.000000000" solimp="0.899999976 0.949999988 0.001000000" friction="1.000000000 0.005000000 0.000100000" solref="0.020000000 1.000000000" margin="0" condim="3" group="0" pos="-4.573544502 0.835462213 2.151423454" quat="1.000000000 0.000000000 0.000000000 0.000000000" size="0.100000001 0.490000010 0.010000000" name="StaticObjcets_geom_4D99C36A_70AD_4690_9FBC_98735B8CFED1"/>
            <geom contype="2" conaffinity="2" density="1000" type="box" material="" rgba="0.500000000 0.500000000 0.500000000 1.000000000" solimp="0.899999976 0.949999988 0.001000000" friction="1.000000000 0.005000000 0.000100000" solref="0.020000000 1.000000000" margin="0" condim="3" group="0" pos="-5.012205601 0.835292637 1.504703879" quat="0.500000417 0.499999970 0.499999970 0.499999553" size="0.449999988 0.600000024 0.010000000" name="StaticObjcets_Fridge_only_08_C05DAD99_5C84_40EA_8532_AF059A050D6B"/>
        </body>
        <body pos="-3.662749529 0.835145235 0.026324987" euler="0.000000000 0.000000000 180.000000000" mocap="true" name="openloong_gripper_2f85_fix_base_usda_leftHandMocap"/>
        <body pos="-3.662749529 0.835145235 0.026324987" euler="0.000000000 0.000000000 180.000000000" mocap="true" name="openloong_gripper_2f85_fix_base_usda_rightHandMocap"/>
        <body pos="-3.662749529 0.835145235 1.226325035" euler="0.000000000 0.000000000 180.000000000" name="openloong_gripper_2f85_fix_base_usda_base_link">
            <geom contype="1" conaffinity="1" density="1000" type="mesh" material="" rgba="0.783999979 0.783999979 0.783999979 1.000000000" solimp="0.899999976 0.949999988 0.001000000" friction="1.000000000 0.005000000 0.000100000" solref="0.020000000 1.000000000" margin="0" condim="3" group="3" mesh="base_link" pos="0.000000000 0.000000000 0.000000000" quat="1.000000000 0.000000000 0.000000000 0.000000000" size="1.000000000 1.000000000 1.000000000" name="openloong_gripper_2f85_fix_base_usda__geom_7_6F4A79AC_D759_4E5D_88DD_7ABA39AA3911"/>
            <site size="0.005000000 0.005000000 0.005000000" rgba="0.500000000 0.500000000 0.500000000 1.000000000" pos="0.000000000 0.000000000 0.000000000" quat="1.000000000 0.000000000 0.000000000 0.000000000" group="0" type="sphere" name="openloong_gripper_2f85_fix_base_usda_imu"/>
            <inertial mass="22.447001" pos="-0.005664100 -0.001336700 0.238289997" diaginertia="0.374352545 0.277180195 0.220617250" quat="0.999247074 0.035235517 -0.015086859 0.006023135"/>
            <body pos="0.000000000 0.000000000 0.299999952" euler="0.000000000 0.000000000 0.000000000" name="openloong_gripper_2f85_fix_base_usda_dummy_body">
                <geom contype="1" conaffinity="1" density="1000" type="sphere" material="" rgba="0.783999979 0.783999979 0.783999979 1.000000000" solimp="0.899999976 0.949999988 0.001000000" friction="1.000000000 0.005000000 0.000100000" solref="0.020000000 1.000000000" margin="0" condim="3" group="3" pos="0.000000000 0.000000000 0.000000000" quat="1.000000000 0.000000000 0.000000000 0.000000000" size="0.010000000 0.000000000 0.000000000" name="openloong_gripper_2f85_fix_base_usda__geom_8_FA4B1CAE_FE6D_4F9A_A0DC_5A1DBF807C75"/>
                <joint armature="0.0099999998" stiffness="0" damping="0.1" axis="0.000000 0.000000 1.000000" type="hinge" name="openloong_gripper_2f85_fix_base_usda_dummy_joint"/>
                <site size="0.010000000 0.005000000 0.005000000" rgba="0.500000000 0.500000000 0.500000000 1.000000000" pos="0.000000000 0.000000000 0.000000000" quat="1.000000000 0.000000000 0.000000000 0.000000000" group="3" type="sphere" name="openloong_gripper_2f85_fix_base_usda_dummy_site"/>
            </body>
            <body pos="0.009000063 0.000000000 0.406399965" euler="0.000000000 0.000000000 0.000000000" name="openloong_gripper_2f85_fix_base_usda_Link_head_yaw">
                <geom contype="1" conaffinity="1" density="1000" type="mesh" material="" rgba="0.783999979 0.783999979 0.783999979 1.000000000" solimp="0.899999976 0.949999988 0.001000000" friction="1.000000000 0.005000000 0.000100000" solref="0.020000000 1.000000000" margin="0" condim="3" group="3" mesh="Link_head_yaw" pos="0.000000000 0.000000000 0.000000000" quat="1.000000000 0.000000000 0.000000000 0.000000000" size="1.000000000 1.000000000 1.000000000" name="openloong_gripper_2f85_fix_base_usda__geom_10_D7CB56F4_1948_4380_91C8_7C37ACB3406A"/>
                <inertial mass="0.84249002" pos="0.000000000 -0.002081400 0.044801001" diaginertia="0.000700588 0.000629000 0.000553812" quat="0.706933022 -0.015675601 0.015677100 0.706933022"/>
                <body pos="0.000000000 -0.034600019 0.048500061" euler="0.000000000 0.000000000 0.000000000" name="openloong_gripper_2f85_fix_base_usda_Link_head_pitch">
                    <geom contype="1" conaffinity="1" density="1000" type="mesh" material="" rgba="0.783999979 0.783999979 0.783999979 1.000000000" solimp="0.899999976 0.949999988 0.001000000" friction="1.000000000 0.005000000 0.000100000" solref="0.020000000 1.000000000" margin="0" condim="3" group="3" mesh="Link_head_pitch" pos="0.000000000 0.000000000 0.000000000" quat="1.000000000 0.000000000 0.000000000 0.000000000" size="1.000000000 1.000000000 1.000000000" name="openloong_gripper_2f85_fix_base_usda__geom_12_427D66CA_A9C1_4E16_A0FD_64B3CC6CC578"/>
                    <inertial mass="1.3943" pos="0.020569000 0.033004001 0.125000000" diaginertia="0.006381400 0.006289940 0.004481460" quat="0.973390222 0.008406822 0.228157058 0.019624906"/>
                    <body pos="0.000000000 0.029999971 0.000000000" euler="0.000000000 0.000000000 0.000000000" name="openloong_gripper_2f85_fix_base_usda_neck_center_body">
                        <site size="0.010000000 0.005000000 0.005000000" rgba="0.500000000 0.500000000 0.500000000 1.000000000" pos="0.000000000 0.000000000 0.000000000" quat="1.000000000 0.000000000 0.000000000 0.000000000" group="3" type="sphere" name="openloong_gripper_2f85_fix_base_usda_neck_center_site"/>
                        <body pos="0.019999981 0.000000000 0.149999976" euler="-0.000002229 39.998176575 -90.000205994" name="openloong_gripper_2f85_fix_base_usda_camera_head">
                            <site size="0.010000000 0.005000000 0.005000000" rgba="0.500000000 0.500000000 0.500000000 1.000000000" pos="0.000000000 0.000000000 0.000000000" quat="1.000000000 0.000000000 0.000000000 0.000000000" group="3" type="sphere" name="openloong_gripper_2f85_fix_base_usda_camera_head_site"/>
                        </body>
                    </body>
                </body>
            </body>
            <body pos="0.003999949 -0.161599994 0.392199993" euler="0.000000000 0.000000000 0.000000000" name="openloong_gripper_2f85_fix_base_usda_Link_arm_r_01">
                <geom contype="1" conaffinity="1" density="1000" type="mesh" material="" rgba="0.783999979 0.783999979 0.783999979 1.000000000" solimp="0.899999976 0.949999988 0.001000000" friction="1.000000000 0.005000000 0.000100000" solref="0.020000000 1.000000000" margin="0" condim="3" group="3" mesh="Link_arm_r_01" pos="0.000000000 0.000000000 0.000000000" quat="1.000000000 0.000000000 0.000000000 0.000000000" size="1.000000000 1.000000000 1.000000000" name="openloong_gripper_2f85_fix_base_usda__geom_14_792DFBA6_BE75_42B5_89FA_44C93B5D28B6"/>
                <joint armature="0.0099999998" stiffness="0" damping="1" axis="0.000000 -1.000000 0.000000" limited="true" range="-170.000015259 170.000015259" type="hinge" name="openloong_gripper_2f85_fix_base_usda_J_arm_r_01"/>
                <inertial mass="0.75641" pos="0.004494600 -0.038293999 -0.000001874" diaginertia="0.000842990 0.000803050 0.000587120" quat="-0.000163502 0.707098067 0.000812463 0.707115054"/>
                <body pos="-0.042000055 -0.041000009 0.000000000" euler="0.000000000 0.000000000 0.000000000" name="openloong_gripper_2f85_fix_base_usda_Link_arm_r_02">
                    <geom contype="1" conaffinity="1" density="1000" type="mesh" material="" rgba="0.783999979 0.783999979 0.783999979 1.000000000" solimp="0.899999976 0.949999988 0.001000000" friction="1.000000000 0.005000000 0.000100000" solref="0.020000000 1.000000000" margin="0" condim="3" group="3" mesh="Link_arm_r_02" pos="0.000000000 0.000000000 0.000000000" quat="1.000000000 0.000000000 0.000000000 0.000000000" size="1.000000000 1.000000000 1.000000000" name="openloong_gripper_2f85_fix_base_usda__geom_16_A185398F_A2FB_45A1_9CA1_9A8E73D32972"/>
                    <joint armature="0.0099999998" stiffness="0" damping="1" axis="-1.000000 0.000000 0.000000" limited="true" range="-105.000244141 105.000244141" type="hinge" name="openloong_gripper_2f85_fix_base_usda_J_arm_r_02"/>
                    <inertial mass="0.98500001" pos="0.041999999 -0.067430697 0.000000000" diaginertia="0.002262690 0.001730990 0.001154020" quat="0.500000000 0.500000000 -0.500000000 0.500000000"/>
                    <body pos="0.042000055 -0.122599959 0.000000000" euler="0.000000000 0.000000000 0.000000000" name="openloong_gripper_2f85_fix_base_usda_Link_arm_r_03">
                        <geom contype="1" conaffinity="1" density="1000" type="mesh" material="" rgba="0.783999979 0.783999979 0.783999979 1.000000000" solimp="0.899999976 0.949999988 0.001000000" friction="1.000000000 0.005000000 0.000100000" solref="0.020000000 1.000000000" margin="0" condim="3" group="3" mesh="Link_arm_r_03" pos="0.000000000 0.000000000 0.000000000" quat="1.000000000 0.000000000 0.000000000 0.000000000" size="1.000000000 1.000000000 1.000000000" name="openloong_gripper_2f85_fix_base_usda__geom_18_66AE9B3F_9E51_45A4_9172_C1B1FF1F16C6"/>
                        <joint armature="0.0099999998" stiffness="0" damping="1" axis="0.000000 -1.000000 0.000000" limited="true" range="-170.000015259 170.000015259" type="hinge" name="openloong_gripper_2f85_fix_base_usda_J_arm_r_03"/>
                        <inertial mass="0.95899999" pos="-0.001413580 -0.164663002 0.020757901" diaginertia="0.002101340 0.002064590 0.000754802" quat="0.560480952 0.454391927 -0.443732947 0.531497955"/>
                        <body pos="0.035300016 -0.177399993 0.024000049" euler="0.000000000 0.000000000 0.000000000" name="openloong_gripper_2f85_fix_base_usda_Link_arm_r_04">
                            <geom contype="1" conaffinity="1" density="1000" type="mesh" material="" rgba="0.783999979 0.783999979 0.783999979 1.000000000" solimp="0.899999976 0.949999988 0.001000000" friction="1.000000000 0.005000000 0.000100000" solref="0.020000000 1.000000000" margin="0" condim="3" group="3" mesh="Link_arm_r_04" pos="0.000000000 0.000000000 0.000000000" quat="1.000000000 0.000000000 0.000000000 0.000000000" size="1.000000000 1.000000000 1.000000000" name="openloong_gripper_2f85_fix_base_usda__geom_20_07131283_37FB_4893_A80D_2DB99D4939DA"/>
                            <joint armature="0.0099999998" stiffness="0" damping="1" axis="-1.000000 0.000000 0.000000" limited="true" range="0.000000000 170.000015259" type="hinge" name="openloong_gripper_2f85_fix_base_usda_J_arm_r_04"/>
                            <inertial mass="0.60000002" pos="-0.038727000 -0.060766999 -0.021003000" diaginertia="0.001092610 0.000712422 0.000645102" quat="0.327701002 0.632602990 -0.467366993 0.523443997"/>
                            <body pos="-0.035300016 -0.103500009 -0.024000049" euler="0.000000000 0.000000000 0.000000000" name="openloong_gripper_2f85_fix_base_usda_Link_arm_r_05">
                                <geom contype="1" conaffinity="1" density="1000" type="mesh" material="" rgba="0.783999979 0.783999979 0.783999979 1.000000000" solimp="0.899999976 0.949999988 0.001000000" friction="1.000000000 0.005000000 0.000100000" solref="0.020000000 1.000000000" margin="0" condim="3" group="3" mesh="Link_arm_r_05" pos="0.000000000 0.000000000 0.000000000" quat="1.000000000 0.000000000 0.000000000 0.000000000" size="1.000000000 1.000000000 1.000000000" name="openloong_gripper_2f85_fix_base_usda__geom_22_2D73845B_9328_4B31_933A_A3D7C2F54A9C"/>
                                <joint armature="0.0099999998" stiffness="0" damping="1" axis="0.000000 -1.000000 0.000000" limited="true" range="-170.000015259 170.000015259" type="hinge" name="openloong_gripper_2f85_fix_base_usda_J_arm_r_05"/>
                                <inertial mass="0.68976003" pos="0.000032712 -0.068658002 -0.000111780" diaginertia="0.002522510 0.002411100 0.000448695" quat="0.707660973 0.706543028 -0.002603360 0.002470550"/>
                                <body pos="-0.026499987 -0.196499944 0.000000000" euler="0.000000000 0.000000000 0.000000000" name="openloong_gripper_2f85_fix_base_usda_Link_arm_r_06">
                                    <geom contype="1" conaffinity="1" density="1000" type="mesh" material="" rgba="0.783999979 0.783999979 0.783999979 1.000000000" solimp="0.899999976 0.949999988 0.001000000" friction="1.000000000 0.005000000 0.000100000" solref="0.020000000 1.000000000" margin="0" condim="3" group="3" mesh="Link_arm_r_06" pos="0.000000000 0.000000000 0.000000000" quat="1.000000000 0.000000000 0.000000000 0.000000000" size="1.000000000 1.000000000 1.000000000" name="openloong_gripper_2f85_fix_base_usda__geom_24_ADCC3D9F_D39C_42B7_8D1A_C0447D65FB17"/>
                                    <joint armature="0.0099999998" stiffness="0" damping="1" axis="1.000000 0.000000 0.000000" limited="true" range="-105.000244141 105.000244141" type="hinge" name="openloong_gripper_2f85_fix_base_usda_J_arm_r_06"/>
                                    <inertial mass="0.28" pos="0.026078001 -0.000000896 0.001663700" diaginertia="0.000156930 0.000145601 0.000104979" quat="0.707080841 0.001851080 0.001883810 0.707127810"/>
                                    <body pos="0.026499987 0.000000000 0.031800032" euler="0.000000000 0.000000000 0.000000000" name="openloong_gripper_2f85_fix_base_usda_Link_arm_r_07">
                                        <geom contype="1" conaffinity="1" density="1000" type="mesh" material="" rgba="0.783999979 0.783999979 0.783999979 1.000000000" solimp="0.899999976 0.949999988 0.001000000" friction="1.000000000 0.005000000 0.000100000" solref="0.020000000 1.000000000" margin="0" condim="3" group="3" mesh="Link_arm_r_07" pos="0.000000000 0.000000000 0.000000000" quat="1.000000000 0.000000000 0.000000000 0.000000000" size="1.000000000 1.000000000 1.000000000" name="openloong_gripper_2f85_fix_base_usda__geom_26_FF143BEF_BD4A_4045_8D25_E62B9256FD5D"/>
                                        <joint armature="0.0099999998" stiffness="0" damping="1" axis="0.000000 0.000000 1.000000" limited="true" range="-60.000133514 60.000133514" type="hinge" name="openloong_gripper_2f85_fix_base_usda_J_arm_r_07"/>
                                        <inertial mass="0.61353999" pos="-0.007859000 -0.158170000 -0.027736001" diaginertia="0.003037610 0.002570910 0.000729379" quat="0.427542925 0.443532884 -0.553093910 0.560867906"/>
                                        <body pos="0.000000000 0.286999941 -0.269999981" euler="150.000350952 0.000000000 0.000000000" name="openloong_gripper_2f85_fix_base_usda_camera_wrist_r">
                                            <site size="0.010000000 0.005000000 0.005000000" rgba="0.500000000 0.500000000 0.500000000 1.000000000" pos="0.000000000 0.000000000 0.000000000" quat="1.000000000 0.000000000 0.000000000 0.000000000" group="3" type="sphere" name="openloong_gripper_2f85_fix_base_usda_camera_wrist_r_site"/>
                                        </body>
                                        <body pos="0.000000000 -0.220000029 -0.032999992" euler="0.000000000 0.000000000 179.999969482" name="openloong_gripper_2f85_fix_base_usda_ee_center_body_r">
                                            <site size="0.010000000 0.005000000 0.005000000" rgba="0.500000000 0.500000000 0.500000000 1.000000000" pos="0.000000000 0.000000000 0.000000000" quat="1.000000000 0.000000000 0.000000000 0.000000000" group="3" type="sphere" name="openloong_gripper_2f85_fix_base_usda_ee_center_site_r"/>
                                        </body>
                                        <body pos="0.000000000 -0.065999985 -0.031000018" euler="89.999984741 0.000000000 180.000000000" name="openloong_gripper_2f85_fix_base_usda_zbr_base_link">
                                            <geom contype="1" conaffinity="1" density="1000" type="mesh" material="" rgba="0.783999979 0.783999979 0.783999979 1.000000000" solimp="0.899999976 0.949999988 0.001000000" friction="1.000000000 0.005000000 0.000100000" solref="0.020000000 1.000000000" margin="0" condim="3" group="3" mesh="base" pos="0.000000000 0.000000000 0.000000000" quat="1.000000000 0.000000000 0.000000000 0.000000000" size="1.000000238 1.000000238 1.000000238" name="openloong_gripper_2f85_fix_base_usda__geom_30_A413E6F5_6779_4D50_B8D2_E6C19F127E84"/>
                                            <inertial mass="0.77744102" pos="0.000000000 -0.000027039 0.035467502" diaginertia="0.000260285 0.000225381 0.000152708" quat="0.999998808 -0.001528488 0.000000000 0.000000000"/>
                                            <body pos="-0.030601032 0.004750133 0.065704480" euler="-89.999977112 0.000000000 0.000000000" name="openloong_gripper_2f85_fix_base_usda_r_left_driver">
                                                <geom contype="1" conaffinity="1" density="1000" type="mesh" material="" rgba="0.783999979 0.783999979 0.783999979 1.000000000" solimp="0.899999976 0.949999988 0.001000000" friction="1.000000000 0.005000000 0.000100000" solref="0.020000000 1.000000000" margin="0" condim="3" group="3" mesh="driver" pos="0.030601032 0.054904357 -0.004699946" quat="0.707106709 0.707106590 0.000000000 0.000000000" size="1.000000238 1.000000238 1.000000238" name="openloong_gripper_2f85_fix_base_usda__geom_32_963217E4_9A59_406A_A067_3CE0D956E36B"/>
                                                <joint armature="0.0049999999" stiffness="0" damping="0.1" axis="0.000000 0.000000 1.000000" limited="true" range="0.000000000 51.566200256" type="hinge" name="openloong_gripper_2f85_fix_base_usda_r_left_driver_joint"/>
                                                <inertial mass="0.0089956298" pos="0.000000000 0.017754700 0.001073140" diaginertia="0.000001724 0.000001609 0.000000322" quat="0.681301236 0.732003212 0.000000000 0.000000000"/>
                                                <body pos="-0.031425007 0.004532219 -0.010200026" euler="0.000000000 0.000000000 180.000000000" name="openloong_gripper_2f85_fix_base_usda_r_left_coupler">
                                                    <geom contype="1" conaffinity="1" density="1000" type="mesh" material="" rgba="0.783999979 0.783999979 0.783999979 1.000000000" solimp="0.899999976 0.949999988 0.001000000" friction="1.000000000 0.005000000 0.000100000" solref="0.020000000 1.000000000" margin="0" condim="3" group="3" mesh="coupler" pos="-0.062026039 -0.050372254 0.005499960" quat="0.707106709 -0.707106590 0.000000000 0.000000000" size="1.000000238 1.000000238 1.000000238" name="openloong_gripper_2f85_fix_base_usda__geom_34_E11301D7_A6F3_4267_9C28_5D033D374EB5"/>
                                                    <inertial mass="0.0140974" pos="0.000000000 0.003012090 0.023217499" diaginertia="0.000004162 0.000003522 0.000000888" quat="0.705635548 -0.045590367 0.045590367 0.705635548"/>
                                                </body>
                                            </body>
                                            <body pos="-0.012700084 -0.011999848 0.072219983" euler="-89.999977112 0.000000000 0.000000000" name="openloong_gripper_2f85_fix_base_usda_r_left_spring_link">
                                                <geom contype="1" conaffinity="1" density="1000" type="mesh" material="" rgba="0.783999979 0.783999979 0.783999979 1.000000000" solimp="0.899999976 0.949999988 0.001000000" friction="1.000000000 0.005000000 0.000100000" solref="0.020000000 1.000000000" margin="0" condim="3" group="3" mesh="spring_link" pos="0.012700084 0.061419860 0.012050035" quat="0.707106709 0.707106590 0.000000000 0.000000000" size="1.000000238 1.000000238 1.000000238" name="openloong_gripper_2f85_fix_base_usda__geom_36_B6DABB27_7185_4AEC_A031_B0A6D199DE8C"/>
                                                <joint armature="0.001" stiffness="0.050000001" damping="0.00125" axis="0.000000 0.000000 1.000000" limited="true" range="-17.000000000 51.566200256" type="hinge" name="openloong_gripper_2f85_fix_base_usda_r_left_spring_link_joint"/>
                                                <inertial mass="0.0221642" pos="-0.000000009 0.018162400 0.021265799" diaginertia="0.000008969 0.000006717 0.000002639" quat="0.663403213 -0.244737089 0.244737089 0.663403213"/>
                                                <body pos="-0.038208015 -0.042500269 0.002950073" euler="180.000000000 0.000000000 -0.002179886" name="openloong_gripper_2f85_fix_base_usda_r_left_follower">
                                                    <geom contype="1" conaffinity="1" density="1000" type="mesh" material="" rgba="0.783999979 0.783999979 0.783999979 1.000000000" solimp="0.899999976 0.949999988 0.001000000" friction="1.000000000 0.005000000 0.000100000" solref="0.020000000 1.000000000" margin="0" condim="3" group="3" mesh="follower" pos="0.050907861 -0.103919886 -0.009099962" quat="0.707106709 -0.707106590 0.000000000 -0.000000000" size="1.000000238 1.000000238 1.000000238" name="openloong_gripper_2f85_fix_base_usda__geom_39_1268D606_2D38_4C2E_8007_602FD1F97A2A"/>
                                                    <geom contype="1" conaffinity="1" density="1000" type="mesh" material="" rgba="0.783999979 0.783999979 0.783999979 1.000000000" solimp="0.899999976 0.949999988 0.001000000" friction="1.000000000 0.005000000 0.000100000" solref="0.020000000 1.000000000" margin="0" condim="3" group="3" mesh="tongue" pos="0.050907861 -0.103919886 -0.009099962" quat="0.707106709 -0.707106590 0.000000000 -0.000000000" size="1.000000238 1.000000238 1.000000238" name="openloong_gripper_2f85_fix_base_usda__geom_40_1A637645_C79F_4C40_BB56_A877B1D975D5"/>
                                                    <joint armature="0.001" stiffness="0" damping="0.1" axis="0.000000 0.000000 1.000000" limited="true" range="-49.999961853 51.566200256" type="hinge" name="openloong_gripper_2f85_fix_base_usda_r_left_follower"/>
                                                    <inertial mass="0.0125222" pos="0.000000000 -0.011046000 0.012478600" diaginertia="0.000002674 0.000002456 0.000000602" quat="0.986436546 0.164143041 0.000000000 0.000000000"/>
                                                    <body pos="-0.037789829 -0.103916071 -0.009099962" euler="-89.999961853 0.000000000 -0.000000000" name="openloong_gripper_2f85_fix_base_usda_r_left_pad">
                                                        <geom contype="1" conaffinity="1" density="1000" type="box" material="" rgba="0.550000012 0.550000012 0.550000012 1.000000000" solimp="0.949999988 0.990000010 0.001000000" friction="0.699999988 0.005000000 0.000100000" solref="0.020000000 1.000000000" margin="0" condim="3" group="3" mass="1e-06" pos="0.043257486 -0.000000119 0.119999796" quat="0.999999821 0.000000000 0.000000000 0.000000000" size="0.002000001 0.011000003 0.009375002" name="openloong_gripper_2f85_fix_base_usda_r_left_pad1_BDA2C3E1_CC97_4BF7_8DB2_1AE557AA9482"/>
                                                        <geom contype="1" conaffinity="1" density="1000" type="box" material="" rgba="0.449999988 0.449999988 0.449999988 1.000000000" solimp="0.949999988 0.990000010 0.001000000" friction="0.600000024 0.005000000 0.000100000" solref="0.020000000 1.000000000" margin="0" condim="3" group="3" mass="1e-06" pos="0.043257724 -0.000000119 0.138749987" quat="0.999999821 0.000000000 0.000000000 0.000000000" size="0.002000001 0.011000003 0.009375002" name="openloong_gripper_2f85_fix_base_usda_r_left_pad2_1A55A69C_61A0_49E7_8CCC_2F72F3F07EC6"/>
                                                    </body>
                                                </body>
                                            </body>
                                            <body pos="0.030601032 -0.004749895 0.065704480" euler="89.999984741 0.000000000 180.000000000" name="openloong_gripper_2f85_fix_base_usda_r_right_driver">
                                                <geom contype="1" conaffinity="1" density="1000" type="mesh" material="" rgba="0.783999979 0.783999979 0.783999979 1.000000000" solimp="0.899999976 0.949999988 0.001000000" friction="1.000000000 0.005000000 0.000100000" solref="0.020000000 1.000000000" margin="0" condim="3" group="3" mesh="driver" pos="0.030601032 0.054904357 -0.004699946" quat="0.707106829 0.707106709 0.000000000 0.000000000" size="1.000000238 1.000000238 1.000000238" name="openloong_gripper_2f85_fix_base_usda__geom_42_41BE24BE_A48D_4A13_A45F_74110358DAFF"/>
                                                <joint armature="0.0049999999" stiffness="0" damping="0.1" axis="0.000000 0.000000 1.000000" limited="true" range="0.000000000 51.566200256" type="hinge" name="openloong_gripper_2f85_fix_base_usda_r_right_driver_joint"/>
                                                <inertial mass="0.0089956298" pos="0.000000000 0.017754700 0.001073140" diaginertia="0.000001724 0.000001609 0.000000322" quat="0.681301236 0.732003212 0.000000000 0.000000000"/>
                                                <body pos="-0.031425007 0.004532219 -0.010200026" euler="0.000000000 0.000000000 180.000000000" name="openloong_gripper_2f85_fix_base_usda_r_right_coupler">
                                                    <geom contype="1" conaffinity="1" density="1000" type="mesh" material="" rgba="0.783999979 0.783999979 0.783999979 1.000000000" solimp="0.899999976 0.949999988 0.001000000" friction="1.000000000 0.005000000 0.000100000" solref="0.020000000 1.000000000" margin="0" condim="3" group="3" mesh="coupler" pos="-0.062026039 -0.050372254 0.005499960" quat="0.707106829 -0.707106709 0.000000000 0.000000000" size="1.000000238 1.000000238 1.000000238" name="openloong_gripper_2f85_fix_base_usda__geom_44_219C1E37_18FC_4659_94CF_D0103B78ABE4"/>
                                                    <inertial mass="0.0140974" pos="0.000000000 0.003012090 0.023217499" diaginertia="0.000004162 0.000003522 0.000000888" quat="0.705635548 -0.045590367 0.045590367 0.705635548"/>
                                                </body>
                                            </body>
                                            <body pos="0.012700084 0.012000087 0.072219983" euler="89.999984741 0.000000000 180.000000000" name="openloong_gripper_2f85_fix_base_usda_r_right_spring_link">
                                                <geom contype="1" conaffinity="1" density="1000" type="mesh" material="" rgba="0.783999979 0.783999979 0.783999979 1.000000000" solimp="0.899999976 0.949999988 0.001000000" friction="1.000000000 0.005000000 0.000100000" solref="0.020000000 1.000000000" margin="0" condim="3" group="3" mesh="spring_link" pos="0.012700084 0.061419860 0.012050035" quat="0.707106829 0.707106709 0.000000000 0.000000000" size="1.000000238 1.000000238 1.000000238" name="openloong_gripper_2f85_fix_base_usda__geom_46_C7285CB4_42F7_4F6A_BF26_DEF265E0A90F"/>
                                                <joint armature="0.001" stiffness="0.050000001" damping="0.00125" axis="0.000000 0.000000 1.000000" limited="true" range="-17.000000000 51.566200256" type="hinge" name="openloong_gripper_2f85_fix_base_usda_r_right_spring_link_joint"/>
                                                <inertial mass="0.0221642" pos="-0.000000009 0.018162400 0.021265799" diaginertia="0.000008969 0.000006717 0.000002639" quat="0.663403213 -0.244737089 0.244737089 0.663403213"/>
                                                <body pos="-0.038208015 -0.042500269 0.002949954" euler="180.000000000 0.000000000 0.000000000" name="openloong_gripper_2f85_fix_base_usda_r_right_follower">
                                                    <geom contype="1" conaffinity="1" density="1000" type="mesh" material="" rgba="0.783999979 0.783999979 0.783999979 1.000000000" solimp="0.899999976 0.949999988 0.001000000" friction="1.000000000 0.005000000 0.000100000" solref="0.020000000 1.000000000" margin="0" condim="3" group="3" mesh="tongue" pos="0.050907861 -0.103919886 -0.009099962" quat="0.707106829 -0.707106709 0.000000000 0.000000000" size="1.000000238 1.000000238 1.000000238" name="openloong_gripper_2f85_fix_base_usda__geom_49_9F74EA30_8C6B_4418_8F6E_1CCB1C718270"/>
                                                    <geom contype="1" conaffinity="1" density="1000" type="mesh" material="" rgba="0.783999979 0.783999979 0.783999979 1.000000000" solimp="0.899999976 0.949999988 0.001000000" friction="1.000000000 0.005000000 0.000100000" solref="0.020000000 1.000000000" margin="0" condim="3" group="3" mesh="follower" pos="0.050907861 -0.103919886 -0.009099962" quat="0.707106829 -0.707106709 0.000000000 0.000000000" size="1.000000238 1.000000238 1.000000238" name="openloong_gripper_2f85_fix_base_usda__geom_50_B9AA8EFA_C771_4244_AE1C_2D01A9783FEA"/>
                                                    <joint armature="0.001" stiffness="0" damping="0.1" axis="0.000000 0.000000 1.000000" limited="true" range="-49.999961853 51.566200256" type="hinge" name="openloong_gripper_2f85_fix_base_usda_r_right_follower_joint"/>
                                                    <inertial mass="0.0125222" pos="0.000000000 -0.011046000 0.012478600" diaginertia="0.000002674 0.000002456 0.000000602" quat="0.986436546 0.164143041 0.000000000 0.000000000"/>
                                                    <body pos="-0.037789829 -0.103915952 -0.009099962" euler="-89.999984741 0.000000000 0.000000000" name="openloong_gripper_2f85_fix_base_usda_r_right_pad">
                                                        <geom contype="1" conaffinity="1" density="1000" type="box" material="" rgba="0.550000012 0.550000012 0.550000012 1.000000000" solimp="0.949999988 0.990000010 0.001000000" friction="0.699999988 0.005000000 0.000100000" solref="0.020000000 1.000000000" margin="0" condim="3" group="3" mass="1e-06" pos="0.043257963 0.000000000 0.119999677" quat="1.000000000 0.000000000 0.000000000 0.000000000" size="0.002000001 0.011000003 0.009375002" name="openloong_gripper_2f85_fix_base_usda_r_right_pad1_5D0B0DFD_7654_43D1_B488_BE02660C04CE"/>
                                                        <geom contype="1" conaffinity="1" density="1000" type="box" material="" rgba="0.449999988 0.449999988 0.449999988 1.000000000" solimp="0.949999988 0.990000010 0.001000000" friction="0.600000024 0.005000000 0.000100000" solref="0.020000000 1.000000000" margin="0" condim="3" group="3" mass="1e-06" pos="0.043257963 0.000000119 0.138750106" quat="1.000000000 0.000000000 0.000000000 0.000000000" size="0.002000001 0.011000003 0.009375002" name="openloong_gripper_2f85_fix_base_usda_r_right_pad2_C11F1AC8_A2F7_413A_BA1E_3C4DA5B2B4B5"/>
                                                    </body>
                                                </body>
                                            </body>
                                        </body>
                                    </body>
                                </body>
                            </body>
                        </body>
                    </body>
                </body>
            </body>
            <body pos="0.003999949 0.161599994 0.392199993" euler="0.000000000 0.000000000 0.000000000" name="openloong_gripper_2f85_fix_base_usda_Link_arm_l_01">
                <geom contype="1" conaffinity="1" density="1000" type="mesh" material="" rgba="0.783999979 0.783999979 0.783999979 1.000000000" solimp="0.899999976 0.949999988 0.001000000" friction="1.000000000 0.005000000 0.000100000" solref="0.020000000 1.000000000" margin="0" condim="3" group="3" mesh="Link_arm_l_01" pos="0.000000000 0.000000000 0.000000000" quat="1.000000000 0.000000000 0.000000000 0.000000000" size="1.000000000 1.000000000 1.000000000" name="openloong_gripper_2f85_fix_base_usda__geom_52_9D7ED51B_B141_4D8D_A7D2_C94367DA507C"/>
                <joint armature="0.0099999998" stiffness="0" damping="1" axis="0.000000 1.000000 0.000000" limited="true" range="-170.000015259 170.000015259" type="hinge" name="openloong_gripper_2f85_fix_base_usda_J_arm_l_01"/>
                <inertial mass="0.75640601" pos="-0.004494650 0.038294200 -0.000001874" diaginertia="0.000842986 0.000803053 0.000587115" quat="-0.000812496 0.707115054 0.000163424 0.707098067"/>
                <body pos="0.042000055 0.041000009 0.000000000" euler="0.000000000 0.000000000 0.000000000" name="openloong_gripper_2f85_fix_base_usda_Link_arm_l_02">
                    <geom contype="1" conaffinity="1" density="1000" type="mesh" material="" rgba="0.783999979 0.783999979 0.783999979 1.000000000" solimp="0.899999976 0.949999988 0.001000000" friction="1.000000000 0.005000000 0.000100000" solref="0.020000000 1.000000000" margin="0" condim="3" group="3" mesh="Link_arm_l_02" pos="0.000000000 0.000000000 0.000000000" quat="1.000000000 0.000000000 0.000000000 0.000000000" size="1.000000000 1.000000000 1.000000000" name="openloong_gripper_2f85_fix_base_usda__geom_54_F04A8AD6_222D_49C2_B4A5_7ABA3B4D41E9"/>
                    <joint armature="0.0099999998" stiffness="0" damping="1" axis="-1.000000 0.000000 0.000000" limited="true" range="-105.000244141 105.000244141" type="hinge" name="openloong_gripper_2f85_fix_base_usda_J_arm_l_02"/>
                    <inertial mass="0.98500001" pos="-0.041999999 0.067430697 0.000000000" diaginertia="0.002262690 0.001730990 0.001154020" quat="0.500000000 0.500000000 -0.500000000 0.500000000"/>
                    <body pos="-0.042000055 0.122600019 0.000000000" euler="0.000000000 0.000000000 0.000000000" name="openloong_gripper_2f85_fix_base_usda_Link_arm_l_03">
                        <geom contype="1" conaffinity="1" density="1000" type="mesh" material="" rgba="0.783999979 0.783999979 0.783999979 1.000000000" solimp="0.899999976 0.949999988 0.001000000" friction="1.000000000 0.005000000 0.000100000" solref="0.020000000 1.000000000" margin="0" condim="3" group="3" mesh="Link_arm_l_03" pos="0.000000000 0.000000000 0.000000000" quat="1.000000000 0.000000000 0.000000000 0.000000000" size="1.000000000 1.000000000 1.000000000" name="openloong_gripper_2f85_fix_base_usda__geom_56_A3E93CF8_3289_437B_932E_00CBB43654B2"/>
                        <joint armature="0.0099999998" stiffness="0" damping="1" axis="0.000000 1.000000 0.000000" limited="true" range="-170.000015259 170.000015259" type="hinge" name="openloong_gripper_2f85_fix_base_usda_J_arm_l_03"/>
                        <inertial mass="0.95899999" pos="0.001413580 0.164663002 0.020757901" diaginertia="0.002101340 0.002064590 0.000754802" quat="0.443732947 0.531497955 -0.560480952 0.454391927"/>
                        <body pos="-0.035300016 0.177399993 0.024000049" euler="0.000000000 0.000000000 0.000000000" name="openloong_gripper_2f85_fix_base_usda_Link_arm_l_04">
                            <geom contype="1" conaffinity="1" density="1000" type="mesh" material="" rgba="0.783999979 0.783999979 0.783999979 1.000000000" solimp="0.899999976 0.949999988 0.001000000" friction="1.000000000 0.005000000 0.000100000" solref="0.020000000 1.000000000" margin="0" condim="3" group="3" mesh="Link_arm_l_04" pos="0.000000000 0.000000000 0.000000000" quat="1.000000000 0.000000000 0.000000000 0.000000000" size="1.000000000 1.000000000 1.000000000" name="openloong_gripper_2f85_fix_base_usda__geom_58_DD3EF654_B5E4_41ED_A89F_48C8D41DC102"/>
                            <joint armature="0.0099999998" stiffness="0" damping="1" axis="1.000000 0.000000 0.000000" limited="true" range="0.000000000 170.000015259" type="hinge" name="openloong_gripper_2f85_fix_base_usda_J_arm_l_04"/>
                            <inertial mass="0.60000002" pos="0.038727000 0.060767200 -0.021003200" diaginertia="0.001092570 0.000712419 0.000645098" quat="0.467370987 0.523440003 -0.327692002 0.632607996"/>
                            <body pos="0.035300016 0.103500009 -0.024000049" euler="0.000000000 0.000000000 0.000000000" name="openloong_gripper_2f85_fix_base_usda_Link_arm_l_05">
                                <geom contype="1" conaffinity="1" density="1000" type="mesh" material="" rgba="0.783999979 0.783999979 0.783999979 1.000000000" solimp="0.899999976 0.949999988 0.001000000" friction="1.000000000 0.005000000 0.000100000" solref="0.020000000 1.000000000" margin="0" condim="3" group="3" mesh="Link_arm_l_05" pos="0.000000000 0.000000000 0.000000000" quat="1.000000000 0.000000000 0.000000000 0.000000000" size="1.000000000 1.000000000 1.000000000" name="openloong_gripper_2f85_fix_base_usda__geom_60_9219A423_E82A_49F9_84CD_7C0CED5CE965"/>
                                <joint armature="0.0099999998" stiffness="0" damping="1" axis="0.000000 1.000000 0.000000" limited="true" range="-170.000015259 170.000015259" type="hinge" name="openloong_gripper_2f85_fix_base_usda_J_arm_l_05"/>
                                <inertial mass="0.68976003" pos="-0.000032712 0.068658002 -0.000111780" diaginertia="0.002522510 0.002411100 0.000448695" quat="0.706543028 0.707660973 0.002470550 -0.002603360"/>
                                <body pos="0.026499987 0.196500003 0.000000000" euler="0.000000000 0.000000000 0.000000000" name="openloong_gripper_2f85_fix_base_usda_Link_arm_l_06">
                                    <geom contype="1" conaffinity="1" density="1000" type="mesh" material="" rgba="0.783999979 0.783999979 0.783999979 1.000000000" solimp="0.899999976 0.949999988 0.001000000" friction="1.000000000 0.005000000 0.000100000" solref="0.020000000 1.000000000" margin="0" condim="3" group="3" mesh="Link_arm_l_06" pos="0.000000000 0.000000000 0.000000000" quat="1.000000000 0.000000000 0.000000000 0.000000000" size="1.000000000 1.000000000 1.000000000" name="openloong_gripper_2f85_fix_base_usda__geom_62_3DE25559_BA9E_4D61_BC81_91D7A7C8C7DE"/>
                                    <joint armature="0.0099999998" stiffness="0" damping="1" axis="-1.000000 0.000000 0.000000" limited="true" range="-105.000244141 105.000244141" type="hinge" name="openloong_gripper_2f85_fix_base_usda_J_arm_l_06"/>
                                    <inertial mass="0.28" pos="-0.026077701 0.000000896 0.001663730" diaginertia="0.000156927 0.000145598 0.000104981" quat="0.707080841 -0.001851280 -0.001884020 0.707127810"/>
                                    <body pos="-0.026499987 0.000000000 0.031800032" euler="0.000000000 0.000000000 0.000000000" name="openloong_gripper_2f85_fix_base_usda_Link_arm_l_07">
                                        <geom contype="1" conaffinity="1" density="1000" type="mesh" material="" rgba="0.783999979 0.783999979 0.783999979 1.000000000" solimp="0.899999976 0.949999988 0.001000000" friction="1.000000000 0.005000000 0.000100000" solref="0.020000000 1.000000000" margin="0" condim="3" group="3" mesh="Link_arm_l_07" pos="0.000000000 0.000000000 0.000000000" quat="1.000000000 0.000000000 0.000000000 0.000000000" size="1.000000000 1.000000000 1.000000000" name="openloong_gripper_2f85_fix_base_usda__geom_64_485429B5_0B49_4610_990B_5B1F33000734"/>
                                        <joint armature="0.0099999998" stiffness="0" damping="1" axis="0.000000 0.000000 1.000000" limited="true" range="-60.000133514 60.000133514" type="hinge" name="openloong_gripper_2f85_fix_base_usda_J_arm_l_07"/>
                                        <inertial mass="0.61353999" pos="-0.007787200 0.157049999 -0.027733000" diaginertia="0.003037200 0.002570420 0.000729374" quat="0.443562120 0.427539080 -0.560871124 0.553070128"/>
                                        <body pos="0.000000000 -0.287000000 -0.269999981" euler="-150.000350952 -0.000000001 179.976669312" name="openloong_gripper_2f85_fix_base_usda_camera_wrist_l">
                                            <site size="0.010000000 0.005000000 0.005000000" rgba="0.500000000 0.500000000 0.500000000 1.000000000" pos="0.000000000 0.000000000 0.000000000" quat="1.000000000 0.000000000 0.000000000 0.000000000" group="3" type="sphere" name="openloong_gripper_2f85_fix_base_usda_camera_wrist_l_site"/>
                                        </body>
                                        <body pos="0.000000000 0.219999999 -0.032999992" euler="0.000000000 0.000000000 0.000000000" name="openloong_gripper_2f85_fix_base_usda_ee_center_body">
                                            <site size="0.010000000 0.005000000 0.005000000" rgba="0.500000000 0.500000000 0.500000000 1.000000000" pos="0.000000000 0.000000000 0.000000000" quat="1.000000000 0.000000000 0.000000000 0.000000000" group="3" type="sphere" name="openloong_gripper_2f85_fix_base_usda_ee_center_site"/>
                                        </body>
                                        <body pos="0.000000000 0.066000000 -0.031000018" euler="-90.000007629 0.000000000 0.000000000" name="openloong_gripper_2f85_fix_base_usda_zbll_base_link">
                                            <geom contype="1" conaffinity="1" density="1000" type="mesh" material="" rgba="0.783999979 0.783999979 0.783999979 1.000000000" solimp="0.899999976 0.949999988 0.001000000" friction="1.000000000 0.005000000 0.000100000" solref="0.020000000 1.000000000" margin="0" condim="3" group="3" mesh="base" pos="0.000000000 0.000000000 0.000000000" quat="1.000000000 0.000000000 0.000000000 0.000000000" size="1.000000000 1.000000000 1.000000000" name="openloong_gripper_2f85_fix_base_usda__geom_68_53DEA38A_5371_40DC_B374_55A21BB9C53F"/>
                                            <inertial mass="0.77744102" pos="0.000000000 -0.000027039 0.035467502" diaginertia="0.000260285 0.000225381 0.000152708" quat="0.999998808 -0.001528488 0.000000000 0.000000000"/>
                                            <body pos="-0.030601025 0.004750252 0.065704346" euler="-89.999992371 0.000000000 0.000000000" name="openloong_gripper_2f85_fix_base_usda_l_left_driver">
                                                <geom contype="1" conaffinity="1" density="1000" type="mesh" material="" rgba="0.783999979 0.783999979 0.783999979 1.000000000" solimp="0.899999976 0.949999988 0.001000000" friction="1.000000000 0.005000000 0.000100000" solref="0.020000000 1.000000000" margin="0" condim="3" group="3" mesh="driver" pos="0.030601025 0.054904491 -0.004699945" quat="0.707106829 0.707106709 0.000000000 0.000000000" size="1.000000000 1.000000000 1.000000000" name="openloong_gripper_2f85_fix_base_usda__geom_70_7AC8CDAB_F2AB_4005_95E0_45A40DE5D450"/>
                                                <joint armature="0.0049999999" stiffness="0" damping="0.1" axis="0.000000 0.000000 1.000000" limited="true" range="0.000000000 51.566200256" type="hinge" name="openloong_gripper_2f85_fix_base_usda_l_left_driver_joint"/>
                                                <inertial mass="0.0089956298" pos="0.000000000 0.017754700 0.001073140" diaginertia="0.000001724 0.000001609 0.000000322" quat="0.681301236 0.732003212 0.000000000 0.000000000"/>
                                                <body pos="-0.031424999 0.004532233 -0.010200024" euler="0.000000000 0.000000000 180.000000000" name="openloong_gripper_2f85_fix_base_usda_l_left_coupler">
                                                    <geom contype="1" conaffinity="1" density="1000" type="mesh" material="" rgba="0.783999979 0.783999979 0.783999979 1.000000000" solimp="0.899999976 0.949999988 0.001000000" friction="1.000000000 0.005000000 0.000100000" solref="0.020000000 1.000000000" margin="0" condim="3" group="3" mesh="coupler" pos="-0.062026024 -0.050372299 0.005499959" quat="0.707106829 -0.707106709 0.000000000 0.000000000" size="1.000000000 1.000000000 1.000000000" name="openloong_gripper_2f85_fix_base_usda__geom_72_C008C2C1_545C_4206_8008_CD906628E178"/>
                                                    <inertial mass="0.0140974" pos="0.000000000 0.003012090 0.023217499" diaginertia="0.000004162 0.000003522 0.000000888" quat="0.705635548 -0.045590367 0.045590367 0.705635548"/>
                                                </body>
                                            </body>
                                            <body pos="-0.012700081 -0.011999846 0.072219968" euler="-89.999992371 0.000000000 0.000000000" name="openloong_gripper_2f85_fix_base_usda_l_left_spring_link">
                                                <geom contype="1" conaffinity="1" density="1000" type="mesh" material="" rgba="0.783999979 0.783999979 0.783999979 1.000000000" solimp="0.899999976 0.949999988 0.001000000" friction="1.000000000 0.005000000 0.000100000" solref="0.020000000 1.000000000" margin="0" condim="3" group="3" mesh="spring_link" pos="0.012700081 0.061420009 0.012050033" quat="0.707106829 0.707106709 0.000000000 0.000000000" size="1.000000000 1.000000000 1.000000000" name="openloong_gripper_2f85_fix_base_usda__geom_74_64B019EC_8894_4694_81DB_AAFDCBCAB1B0"/>
                                                <joint armature="0.001" stiffness="0.050000001" damping="0.00125" axis="0.000000 0.000000 1.000000" limited="true" range="-17.000000000 51.566200256" type="hinge" name="openloong_gripper_2f85_fix_base_usda_l_left_spring_link_joint"/>
                                                <inertial mass="0.0221642" pos="-0.000000009 0.018162400 0.021265799" diaginertia="0.000008969 0.000006717 0.000002639" quat="0.663403213 -0.244737089 0.244737089 0.663403213"/>
                                                <body pos="-0.038208008 -0.042500287 0.002949953" euler="180.000000000 0.000000000 -0.002179887" name="openloong_gripper_2f85_fix_base_usda_l_left_follower">
                                                    <geom contype="1" conaffinity="1" density="1000" type="mesh" material="" rgba="0.783999979 0.783999979 0.783999979 1.000000000" solimp="0.899999976 0.949999988 0.001000000" friction="1.000000000 0.005000000 0.000100000" solref="0.020000000 1.000000000" margin="0" condim="3" group="3" mesh="follower" pos="0.050908089 -0.103920005 -0.009099960" quat="0.707106829 -0.707106709 0.000000000 -0.000000000" size="1.000000000 1.000000000 1.000000000" name="openloong_gripper_2f85_fix_base_usda__geom_77_56028323_B5CF_45AF_8344_D03CAEC3FDFA"/>
                                                    <geom contype="1" conaffinity="1" density="1000" type="mesh" material="" rgba="0.783999979 0.783999979 0.783999979 1.000000000" solimp="0.899999976 0.949999988 0.001000000" friction="1.000000000 0.005000000 0.000100000" solref="0.020000000 1.000000000" margin="0" condim="3" group="3" mesh="tongue" pos="0.050908089 -0.103920005 -0.009099960" quat="0.707106829 -0.707106709 0.000000000 -0.000000000" size="1.000000000 1.000000000 1.000000000" name="openloong_gripper_2f85_fix_base_usda__geom_78_13C5EFF2_4414_4E91_9CAD_D599E7784C64"/>
                                                    <joint armature="0.001" stiffness="0" damping="0.1" axis="0.000000 0.000000 1.000000" limited="true" range="-49.999961853 51.566200256" type="hinge" name="openloong_gripper_2f85_fix_base_usda_l_left_follower"/>
                                                    <inertial mass="0.0125222" pos="0.000000000 -0.011046000 0.012478600" diaginertia="0.000002674 0.000002456 0.000000602" quat="0.986436546 0.164143041 0.000000000 0.000000000"/>
                                                    <body pos="-0.037789583 -0.103916004 -0.009099960" euler="-89.999984741 0.000000000 -0.000000000" name="openloong_gripper_2f85_fix_base_usda_l_left_pad">
                                                        <geom contype="1" conaffinity="1" density="1000" type="box" material="" rgba="0.449999988 0.449999988 0.449999988 1.000000000" solimp="0.949999988 0.990000010 0.001000000" friction="0.600000024 0.005000000 0.000100000" solref="0.020000000 1.000000000" margin="0" condim="3" group="3" mass="1e-06" pos="0.043257952 0.000000000 0.138750181" quat="1.000000000 0.000000000 0.000000000 0.000000000" size="0.002000000 0.011000000 0.009375000" name="openloong_gripper_2f85_fix_base_usda_l_left_pad2_569FBC7D_4807_47F2_A608_F56ACBF8005F"/>
                                                        <geom contype="1" conaffinity="1" density="1000" type="box" material="" rgba="0.550000012 0.550000012 0.550000012 1.000000000" solimp="0.949999988 0.990000010 0.001000000" friction="0.699999988 0.005000000 0.000100000" solref="0.020000000 1.000000000" margin="0" condim="3" group="3" mass="1e-06" pos="0.043257952 0.000000000 0.119999990" quat="1.000000000 0.000000000 0.000000000 0.000000000" size="0.002000000 0.011000000 0.009375000" name="openloong_gripper_2f85_fix_base_usda_l_left_pad1_18CD5719_396B_4128_992D_835D5DE10F70"/>
                                                    </body>
                                                </body>
                                            </body>
                                            <body pos="0.030601025 -0.004749894 0.065704346" euler="89.999992371 0.000000000 180.000000000" name="openloong_gripper_2f85_fix_base_usda_l_right_driver">
                                                <geom contype="1" conaffinity="1" density="1000" type="mesh" material="" rgba="0.783999979 0.783999979 0.783999979 1.000000000" solimp="0.899999976 0.949999988 0.001000000" friction="1.000000000 0.005000000 0.000100000" solref="0.020000000 1.000000000" margin="0" condim="3" group="3" mesh="driver" pos="0.030601025 0.054904498 -0.004699945" quat="0.707106829 0.707106709 0.000000000 0.000000000" size="1.000000000 1.000000000 1.000000000" name="openloong_gripper_2f85_fix_base_usda__geom_80_F86A68A1_F725_41AC_BB91_EFC65434EFBF"/>
                                                <joint armature="0.0049999999" stiffness="0" damping="0.1" axis="0.000000 0.000000 1.000000" limited="true" range="0.000000000 51.566200256" type="hinge" name="openloong_gripper_2f85_fix_base_usda_l_right_driver_joint"/>
                                                <inertial mass="0.0089956298" pos="0.000000000 0.017754700 0.001073140" diaginertia="0.000001724 0.000001609 0.000000322" quat="0.681301236 0.732003212 0.000000000 0.000000000"/>
                                                <body pos="-0.031424999 0.004532233 -0.010200024" euler="0.000000000 0.000000000 180.000000000" name="openloong_gripper_2f85_fix_base_usda_l_right_coupler">
                                                    <geom contype="1" conaffinity="1" density="1000" type="mesh" material="" rgba="0.783999979 0.783999979 0.783999979 1.000000000" solimp="0.899999976 0.949999988 0.001000000" friction="1.000000000 0.005000000 0.000100000" solref="0.020000000 1.000000000" margin="0" condim="3" group="3" mesh="coupler" pos="-0.062026024 -0.050372299 0.005499959" quat="0.707106829 -0.707106709 0.000000000 0.000000000" size="1.000000000 1.000000000 1.000000000" name="openloong_gripper_2f85_fix_base_usda__geom_82_ACF8AC74_73AD_45F3_84CE_66A35490F708"/>
                                                    <inertial mass="0.0140974" pos="0.000000000 0.003012090 0.023217499" diaginertia="0.000004162 0.000003522 0.000000888" quat="0.705635548 -0.045590367 0.045590367 0.705635548"/>
                                                </body>
                                            </body>
                                            <body pos="0.012700081 0.012000084 0.072219968" euler="89.999992371 0.000000000 180.000000000" name="openloong_gripper_2f85_fix_base_usda_l_right_spring_link">
                                                <geom contype="1" conaffinity="1" density="1000" type="mesh" material="" rgba="0.783999979 0.783999979 0.783999979 1.000000000" solimp="0.899999976 0.949999988 0.001000000" friction="1.000000000 0.005000000 0.000100000" solref="0.020000000 1.000000000" margin="0" condim="3" group="3" mesh="spring_link" pos="0.012700081 0.061420005 0.012050033" quat="0.707106829 0.707106709 0.000000000 0.000000000" size="1.000000000 1.000000000 1.000000000" name="openloong_gripper_2f85_fix_base_usda__geom_84_96857CFF_C578_4FAB_9316_9BBEB07B169A"/>
                                                <joint armature="0.001" stiffness="0.050000001" damping="0.00125" axis="0.000000 0.000000 1.000000" limited="true" range="-17.000000000 51.566200256" type="hinge" name="openloong_gripper_2f85_fix_base_usda_l_right_spring_link_joint"/>
                                                <inertial mass="0.0221642" pos="-0.000000009 0.018162400 0.021265799" diaginertia="0.000008969 0.000006717 0.000002639" quat="0.663403213 -0.244737089 0.244737089 0.663403213"/>
                                                <body pos="-0.038208008 -0.042500295 0.002949953" euler="180.000000000 0.000000000 0.000000000" name="openloong_gripper_2f85_fix_base_usda_l_right_follower">
                                                    <geom contype="1" conaffinity="1" density="1000" type="mesh" material="" rgba="0.783999979 0.783999979 0.783999979 1.000000000" solimp="0.899999976 0.949999988 0.001000000" friction="1.000000000 0.005000000 0.000100000" solref="0.020000000 1.000000000" margin="0" condim="3" group="3" mesh="tongue" pos="0.050907850 -0.103919998 -0.009100080" quat="0.707106829 -0.707106709 0.000000000 0.000000000" size="1.000000000 1.000000000 1.000000000" name="openloong_gripper_2f85_fix_base_usda__geom_87_7FFC6A5C_4B7A_4D42_982D_8FC3D4170016"/>
                                                    <geom contype="1" conaffinity="1" density="1000" type="mesh" material="" rgba="0.783999979 0.783999979 0.783999979 1.000000000" solimp="0.899999976 0.949999988 0.001000000" friction="1.000000000 0.005000000 0.000100000" solref="0.020000000 1.000000000" margin="0" condim="3" group="3" mesh="follower" pos="0.050907850 -0.103919998 -0.009100080" quat="0.707106829 -0.707106709 0.000000000 0.000000000" size="1.000000000 1.000000000 1.000000000" name="openloong_gripper_2f85_fix_base_usda__geom_88_DD104718_C46C_4602_82B1_FEB4B7EF0A45"/>
                                                    <joint armature="0.001" stiffness="0" damping="0.1" axis="0.000000 0.000000 1.000000" limited="true" range="-49.999961853 51.566200256" type="hinge" name="openloong_gripper_2f85_fix_base_usda_l_right_follower_joint"/>
                                                    <inertial mass="0.0125222" pos="0.000000000 -0.011046000 0.012478600" diaginertia="0.000002674 0.000002456 0.000000602" quat="0.986436546 0.164143041 0.000000000 0.000000000"/>
                                                    <body pos="-0.037789583 -0.103915997 -0.009100080" euler="-89.999984741 0.000000000 0.000000000" name="openloong_gripper_2f85_fix_base_usda_l_right_pad">
                                                        <geom contype="1" conaffinity="1" density="1000" type="box" material="" rgba="0.449999988 0.449999988 0.449999988 1.000000000" solimp="0.949999988 0.990000010 0.001000000" friction="0.600000024 0.005000000 0.000100000" solref="0.020000000 1.000000000" margin="0" condim="3" group="3" mass="1e-06" pos="0.043257952 0.000000119 0.138749987" quat="1.000000000 0.000000000 0.000000000 0.000000000" size="0.002000000 0.011000000 0.009375000" name="openloong_gripper_2f85_fix_base_usda_l_right_pad2_F1C3E946_D54A_4198_AE1E_00E03A1BA467"/>
                                                        <geom contype="1" conaffinity="1" density="1000" type="box" material="" rgba="0.550000012 0.550000012 0.550000012 1.000000000" solimp="0.949999988 0.990000010 0.001000000" friction="0.699999988 0.005000000 0.000100000" solref="0.020000000 1.000000000" margin="0" condim="3" group="3" mass="1e-06" pos="0.043257952 0.000000000 0.119999975" quat="1.000000000 0.000000000 0.000000000 0.000000000" size="0.002000000 0.011000000 0.009375000" name="openloong_gripper_2f85_fix_base_usda_l_right_pad1_2A0CC9DD_47CB_4F2C_86BC_986513D677BF"/>
                                                    </body>
                                                </body>
                                            </body>
                                        </body>
                                    </body>
                                </body>
                            </body>
                        </body>
                    </body>
                </body>
            </body>
            <body pos="0.000000000 -0.065249979 0.000000000" euler="0.000000000 0.000000000 0.000000000" name="openloong_gripper_2f85_fix_base_usda_Link_waist_pitch">
                <geom contype="1" conaffinity="1" density="1000" type="mesh" material="" rgba="0.783999979 0.783999979 0.783999979 1.000000000" solimp="0.899999976 0.949999988 0.001000000" friction="1.000000000 0.005000000 0.000100000" solref="0.020000000 1.000000000" margin="0" condim="3" group="3" mesh="Link_waist_pitch" pos="0.000000000 0.000000000 0.000000000" quat="1.000000000 0.000000000 0.000000000 0.000000000" size="1.000000000 1.000000000 1.000000000" name="openloong_gripper_2f85_fix_base_usda__geom_90_559AFC5C_8283_440D_941A_7083480BD122"/>
                <inertial mass="2.6963999" pos="-0.000734960 0.049924999 -0.000029695" diaginertia="0.006190620 0.005201250 0.004737120" quat="0.524125040 0.474713057 -0.522095084 0.476820052"/>
                <body pos="-0.063999891 0.065500021 0.000000000" euler="0.000000000 0.000000000 0.000000000" name="openloong_gripper_2f85_fix_base_usda_Link_waist_roll">
                    <geom contype="1" conaffinity="1" density="1000" type="mesh" material="" rgba="0.783999979 0.783999979 0.783999979 1.000000000" solimp="0.899999976 0.949999988 0.001000000" friction="1.000000000 0.005000000 0.000100000" solref="0.020000000 1.000000000" margin="0" condim="3" group="3" mesh="Link_waist_roll" pos="0.000000000 0.000000000 0.000000000" quat="1.000000000 0.000000000 0.000000000 0.000000000" size="1.000000000 1.000000000 1.000000000" name="openloong_gripper_2f85_fix_base_usda__geom_92_47F47043_560F_46ED_8E14_65F9C177D851"/>
                    <inertial mass="2.9806001" pos="-0.003742400 -0.001000000 -0.016856000" diaginertia="0.018825000 0.017314700 0.005873970" quat="0.576995134 0.408750087 0.408750087 0.576995134"/>
                    <body pos="0.067500114 0.000000000 -0.098000050" euler="0.000000000 0.000000000 0.000000000" name="openloong_gripper_2f85_fix_base_usda_Link_waist_yaw">
                        <geom contype="1" conaffinity="1" density="1000" type="mesh" material="" rgba="0.783999979 0.783999979 0.783999979 1.000000000" solimp="0.899999976 0.949999988 0.001000000" friction="1.000000000 0.005000000 0.000100000" solref="0.020000000 1.000000000" margin="0" condim="3" group="3" mesh="Link_waist_yaw" pos="0.000000000 0.000000000 0.000000000" quat="1.000000000 0.000000000 0.000000000 0.000000000" size="1.000000000 1.000000000 1.000000000" name="openloong_gripper_2f85_fix_base_usda__geom_94_5627B364_623C_4027_A518_B608B6948B74"/>
                        <inertial mass="7.3587999" pos="-0.096171997 -0.001000000 -0.057836000" diaginertia="0.109522998 0.089752100 0.032765999" quat="0.571972013 0.571972013 -0.415749997 0.415749997"/>
                        <body pos="-0.087500095 -0.120000005 -0.069000006" euler="0.000000000 0.000000000 0.000000000" name="openloong_gripper_2f85_fix_base_usda_Link_hip_r_roll">
                            <geom contype="1" conaffinity="1" density="1000" type="mesh" material="" rgba="0.783999979 0.783999979 0.783999979 1.000000000" solimp="0.899999976 0.949999988 0.001000000" friction="1.000000000 0.005000000 0.000100000" solref="0.020000000 1.000000000" margin="0" condim="3" group="3" mesh="Link_hip_r_roll" pos="0.000000000 0.000000000 0.000000000" quat="1.000000000 0.000000000 0.000000000 0.000000000" size="1.000000000 1.000000000 1.000000000" name="openloong_gripper_2f85_fix_base_usda__geom_96_2D47D23D_C16C_47DE_A806_1F9953E73AA8"/>
                            <inertial mass="2.4333999" pos="0.075724997 -0.001061600 0.016590999" diaginertia="0.004506770 0.003996270 0.003606060" quat="0.357336968 0.610613942 0.606069922 0.363510966"/>
                            <body pos="0.082250118 -0.000999987 -0.009999990" euler="0.000000000 0.000000000 0.000000000" name="openloong_gripper_2f85_fix_base_usda_Link_hip_r_yaw">
                                <geom contype="1" conaffinity="1" density="1000" type="mesh" material="" rgba="0.783999979 0.783999979 0.783999979 1.000000000" solimp="0.899999976 0.949999988 0.001000000" friction="1.000000000 0.005000000 0.000100000" solref="0.020000000 1.000000000" margin="0" condim="3" group="3" mesh="Link_hip_r_yaw" pos="0.000000000 0.000000000 0.000000000" quat="1.000000000 0.000000000 0.000000000 0.000000000" size="1.000000000 1.000000000 1.000000000" name="openloong_gripper_2f85_fix_base_usda__geom_98_DB3B04F7_C0AE_467B_9F47_4603FB74D97B"/>
                                <inertial mass="3.4303" pos="-0.000000031 -0.007135600 -0.100630000" diaginertia="0.008090100 0.007736500 0.006631600" quat="0.706536055 0.028403703 -0.028403703 0.706536055"/>
                                <body pos="0.000000000 0.036750019 -0.105499983" euler="0.000000000 0.000000000 0.000000000" name="openloong_gripper_2f85_fix_base_usda_Link_hip_r_pitch">
                                    <geom contype="1" conaffinity="1" density="1000" type="mesh" material="" rgba="0.783999979 0.783999979 0.783999979 1.000000000" solimp="0.899999976 0.949999988 0.001000000" friction="1.000000000 0.005000000 0.000100000" solref="0.020000000 1.000000000" margin="0" condim="3" group="3" mesh="Link_hip_r_pitch" pos="0.000000000 0.000000000 0.000000000" quat="1.000000000 0.000000000 0.000000000 0.000000000" size="1.000000000 1.000000000 1.000000000" name="openloong_gripper_2f85_fix_base_usda__geom_100_A9FA57DB_967F_4538_9CA3_6DEA31C8FBC6"/>
                                    <inertial mass="5.2378001" pos="0.001085600 -0.054970000 -0.145349994" diaginertia="0.043490201 0.037812300 0.015138500" quat="0.999495864 -0.015916798 0.013696698 0.023812896"/>
                                    <body pos="0.000000000 -0.011250019 -0.399999976" euler="0.000000000 0.000000000 0.000000000" name="openloong_gripper_2f85_fix_base_usda_Link_knee_r_pitch">
                                        <geom contype="1" conaffinity="1" density="1000" type="mesh" material="" rgba="0.783999979 0.783999979 0.783999979 1.000000000" solimp="0.899999976 0.949999988 0.001000000" friction="1.000000000 0.005000000 0.000100000" solref="0.020000000 1.000000000" margin="0" condim="3" group="3" mesh="Link_knee_r_pitch" pos="0.000000000 0.000000000 0.000000000" quat="1.000000000 0.000000000 0.000000000 0.000000000" size="1.000000000 1.000000000 1.000000000" name="openloong_gripper_2f85_fix_base_usda__geom_102_36D9A851_9CBF_45E9_BD6E_1327C3058D99"/>
                                        <inertial mass="2.9775" pos="-0.009642500 0.000002934 -0.136010006" diaginertia="0.024215899 0.023851801 0.002284610" quat="0.782037616 -0.003061678 0.016178992 0.623013675"/>
                                        <body pos="0.000000000 0.000000000 -0.386999995" euler="0.000000000 0.000000000 0.000000000" name="openloong_gripper_2f85_fix_base_usda_Link_ankle_r_pitch">
                                            <geom contype="1" conaffinity="1" density="1000" type="mesh" material="" rgba="0.783999979 0.783999979 0.783999979 1.000000000" solimp="0.899999976 0.949999988 0.001000000" friction="1.000000000 0.005000000 0.000100000" solref="0.020000000 1.000000000" margin="0" condim="3" group="3" mesh="Link_ankle_r_pitch" pos="0.000000000 0.000000000 0.000000000" quat="1.000000000 0.000000000 0.000000000 0.000000000" size="1.000000000 1.000000000 1.000000000" name="openloong_gripper_2f85_fix_base_usda__geom_104_64AC1A89_AADC_4938_A8A1_C3200F4BB5D4"/>
                                            <inertial mass="0.10145" pos="-0.000000000 -0.000000127 -0.000000025" diaginertia="0.000027175 0.000026565 0.000006112" quat="0.707106829 0.707106829 0.000000000 0.000000000"/>
                                            <body pos="0.000000000 0.000000000 0.000000000" euler="0.000000000 0.000000000 0.000000000" name="openloong_gripper_2f85_fix_base_usda_Link_ankle_r_roll">
                                                <geom contype="1" conaffinity="1" density="1000" type="box" material="" rgba="1.000000000 0.000000000 0.000000000 0.000000000" solimp="0.899999976 0.949999988 0.001000000" friction="1.000000000 0.005000000 0.000100000" solref="0.020000000 1.000000000" margin="0" condim="3" group="3" pos="0.047504663 0.000082672 -0.026545316" quat="1.000000000 0.000000000 0.000000000 0.000000000" size="0.122500002 0.039999999 0.043499999" name="openloong_gripper_2f85_fix_base_usda__geom_106_1A3F5158_B5AA_4BB5_9B01_06FF653086D2"/>
                                                <site size="0.123000003 0.041000001 0.044000000" rgba="0.000000000 1.000000000 0.000000000 0.000000000" pos="0.047504615 0.000082667 -0.026545310" quat="1.000000000 0.000000000 0.000000000 0.000000000" group="3" type="box" name="openloong_gripper_2f85_fix_base_usda_rf-tc"/>
                                                <inertial mass="0.75229001" pos="0.041078001 -0.000000089 -0.043908998" diaginertia="0.003659370 0.003646500 0.000416828" quat="0.000000000 0.677034914 0.000000000 0.735950947"/>
                                            </body>
                                        </body>
                                    </body>
                                </body>
                            </body>
                        </body>
                        <body pos="-0.087500095 0.120000005 -0.069000006" euler="0.000000000 0.000000000 0.000000000" name="openloong_gripper_2f85_fix_base_usda_Link_hip_l_roll">
                            <geom contype="1" conaffinity="1" density="1000" type="mesh" material="" rgba="0.783999979 0.783999979 0.783999979 1.000000000" solimp="0.899999976 0.949999988 0.001000000" friction="1.000000000 0.005000000 0.000100000" solref="0.020000000 1.000000000" margin="0" condim="3" group="3" mesh="Link_hip_l_roll" pos="0.000000000 0.000000000 0.000000000" quat="1.000000000 0.000000000 0.000000000 0.000000000" size="1.000000000 1.000000000 1.000000000" name="openloong_gripper_2f85_fix_base_usda__geom_108_07DCA67B_6224_4311_B00F_14C9859D1C6E"/>
                            <inertial mass="2.4333999" pos="0.075724997 -0.000938430 0.016590999" diaginertia="0.004257030 0.003974770 0.003377790" quat="0.411751240 0.573205352 0.583885372 0.401216239"/>
                            <body pos="0.082250118 -0.000999987 -0.009999990" euler="0.000000000 0.000000000 0.000000000" name="openloong_gripper_2f85_fix_base_usda_Link_hip_l_yaw">
                                <geom contype="1" conaffinity="1" density="1000" type="mesh" material="" rgba="0.783999979 0.783999979 0.783999979 1.000000000" solimp="0.899999976 0.949999988 0.001000000" friction="1.000000000 0.005000000 0.000100000" solref="0.020000000 1.000000000" margin="0" condim="3" group="3" mesh="Link_hip_l_yaw" pos="0.000000000 0.000000000 0.000000000" quat="1.000000000 0.000000000 0.000000000 0.000000000" size="1.000000000 1.000000000 1.000000000" name="openloong_gripper_2f85_fix_base_usda__geom_110_EE4B8135_7654_4203_B391_F41C8DF663DF"/>
                                <inertial mass="3.4303999" pos="-0.000000032 0.007135800 -0.100630000" diaginertia="0.008090100 0.007736500 0.006631500" quat="0.706536174 -0.028401807 0.028401807 0.706536174"/>
                                <body pos="0.000000000 -0.036750019 -0.105499983" euler="0.000000000 0.000000000 0.000000000" name="openloong_gripper_2f85_fix_base_usda_Link_hip_l_pitch">
                                    <geom contype="1" conaffinity="1" density="1000" type="mesh" material="" rgba="0.783999979 0.783999979 0.783999979 1.000000000" solimp="0.899999976 0.949999988 0.001000000" friction="1.000000000 0.005000000 0.000100000" solref="0.020000000 1.000000000" margin="0" condim="3" group="3" mesh="Link_hip_l_pitch" pos="0.000000000 0.000000000 0.000000000" quat="1.000000000 0.000000000 0.000000000 0.000000000" size="1.000000000 1.000000000 1.000000000" name="openloong_gripper_2f85_fix_base_usda__geom_112_7B5CC157_E0D8_4705_9918_2859358B1720"/>
                                    <inertial mass="5.2378001" pos="0.001085600 0.054970000 -0.145349994" diaginertia="0.043490201 0.037812300 0.015138500" quat="0.999495745 0.015916597 0.013696796 -0.023821594"/>
                                    <body pos="0.000000000 0.011250019 -0.399999976" euler="0.000000000 0.000000000 0.000000000" name="openloong_gripper_2f85_fix_base_usda_Link_knee_l_pitch">
                                        <geom contype="1" conaffinity="1" density="1000" type="mesh" material="" rgba="0.783999979 0.783999979 0.783999979 1.000000000" solimp="0.899999976 0.949999988 0.001000000" friction="1.000000000 0.005000000 0.000100000" solref="0.020000000 1.000000000" margin="0" condim="3" group="3" mesh="Link_knee_l_pitch" pos="0.000000000 0.000000000 0.000000000" quat="1.000000000 0.000000000 0.000000000 0.000000000" size="1.000000000 1.000000000 1.000000000" name="openloong_gripper_2f85_fix_base_usda__geom_114_7B27B405_F79E_4992_B52A_BC84223B8E6C"/>
                                        <inertial mass="2.9775" pos="-0.009642500 -0.000002868 -0.136010006" diaginertia="0.024214899 0.023850800 0.002284610" quat="0.623014212 0.016178306 -0.003060011 0.782037318"/>
                                        <body pos="0.000000000 0.000000000 -0.386999995" euler="0.000000000 0.000000000 0.000000000" name="openloong_gripper_2f85_fix_base_usda_Link_ankle_l_pitch">
                                            <geom contype="1" conaffinity="1" density="1000" type="mesh" material="" rgba="0.783999979 0.783999979 0.783999979 1.000000000" solimp="0.899999976 0.949999988 0.001000000" friction="1.000000000 0.005000000 0.000100000" solref="0.020000000 1.000000000" margin="0" condim="3" group="3" mesh="Link_ankle_l_pitch" pos="0.000000000 0.000000000 0.000000000" quat="1.000000000 0.000000000 0.000000000 0.000000000" size="1.000000000 1.000000000 1.000000000" name="openloong_gripper_2f85_fix_base_usda__geom_116_FE353382_0D90_4546_B8DE_5D38DB454EFC"/>
                                            <inertial mass="0.10145" pos="-0.000000000 0.000000127 0.000000067" diaginertia="0.000027175 0.000026565 0.000006112" quat="0.707106829 0.707106829 0.000000000 0.000000000"/>
                                            <body pos="0.000000000 0.000000000 0.000000000" euler="0.000000000 0.000000000 0.000000000" name="openloong_gripper_2f85_fix_base_usda_Link_ankle_l_roll">
                                                <geom contype="1" conaffinity="1" density="1000" type="box" material="" rgba="1.000000000 0.000000000 0.000000000 0.000000000" solimp="0.899999976 0.949999988 0.001000000" friction="1.000000000 0.005000000 0.000100000" solref="0.020000000 1.000000000" margin="0" condim="3" group="3" pos="0.047499895 0.001220882 -0.027223989" quat="1.000000000 0.000000000 0.000000000 0.000000000" size="0.122500002 0.040199999 0.044199999" name="openloong_gripper_2f85_fix_base_usda__geom_118_27685EF5_2E1F_48BD_A11C_9004FA42847F"/>
                                                <site size="0.123000003 0.041000001 0.045000002" rgba="0.000000000 1.000000000 0.000000000 0.000000000" pos="0.047499999 0.001220864 -0.027223988" quat="1.000000000 0.000000000 0.000000000 0.000000000" group="3" type="box" name="openloong_gripper_2f85_fix_base_usda_lf-tc"/>
                                                <inertial mass="0.75228798" pos="0.041076999 -0.000000029 -0.043908998" diaginertia="0.003659370 0.003646500 0.000416828" quat="0.000000000 0.677034914 0.000000000 0.735950947"/>
                                            </body>
                                        </body>
                                    </body>
                                </body>
                            </body>
                        </body>
                    </body>
                </body>
            </body>
        </body>
    </worldbody>
    <tendon>
        <fixed name="openloong_gripper_2f85_fix_base_usda_l_split">
            <joint joint="openloong_gripper_2f85_fix_base_usda_l_right_driver_joint" coef="0.48500001"/>
            <joint joint="openloong_gripper_2f85_fix_base_usda_l_left_driver_joint" coef="0.48500001"/>
        </fixed>
        <fixed name="openloong_gripper_2f85_fix_base_usda_r_split">
            <joint joint="openloong_gripper_2f85_fix_base_usda_r_right_driver_joint" coef="0.48500001"/>
            <joint joint="openloong_gripper_2f85_fix_base_usda_r_left_driver_joint" coef="0.48500001"/>
        </fixed>
    </tendon>
    <actuator>
        <position ctrllimited="true" ctrlrange="-2.96706 2.96706" forcelimited="true" forcerange="-80 80" joint="openloong_gripper_2f85_fix_base_usda_J_arm_l_01" kp="200" kv="20" name="openloong_gripper_2f85_fix_base_usda_P_arm_l_01"/>
        <position ctrllimited="true" ctrlrange="-1.8326 1.8326" forcelimited="true" forcerange="-80 80" joint="openloong_gripper_2f85_fix_base_usda_J_arm_l_02" kp="200" kv="20" name="openloong_gripper_2f85_fix_base_usda_P_arm_l_02"/>
        <position ctrllimited="true" ctrlrange="-2.96706 2.96706" forcelimited="true" forcerange="-48 48" joint="openloong_gripper_2f85_fix_base_usda_J_arm_l_03" kp="200" kv="20" name="openloong_gripper_2f85_fix_base_usda_P_arm_l_03"/>
        <position ctrllimited="true" ctrlrange="0 2.96706" forcelimited="true" forcerange="-48 48" joint="openloong_gripper_2f85_fix_base_usda_J_arm_l_04" kp="200" kv="20" name="openloong_gripper_2f85_fix_base_usda_P_arm_l_04"/>
        <position ctrllimited="true" ctrlrange="-2.96706 2.96706" forcelimited="true" forcerange="-12.4 12.4" joint="openloong_gripper_2f85_fix_base_usda_J_arm_l_05" kp="200" kv="20" name="openloong_gripper_2f85_fix_base_usda_P_arm_l_05"/>
        <position ctrllimited="true" ctrlrange="-1.8326 1.8326" forcelimited="true" forcerange="-12.4 12.4" joint="openloong_gripper_2f85_fix_base_usda_J_arm_l_06" kp="200" kv="20" name="openloong_gripper_2f85_fix_base_usda_P_arm_l_06"/>
        <position ctrllimited="true" ctrlrange="-1.0472 1.0472" forcelimited="true" forcerange="-12.4 12.4" joint="openloong_gripper_2f85_fix_base_usda_J_arm_l_07" kp="200" kv="20" name="openloong_gripper_2f85_fix_base_usda_P_arm_l_07"/>
        <motor ctrllimited="true" ctrlrange="-80 80" gear="1" joint="openloong_gripper_2f85_fix_base_usda_J_arm_l_01" name="openloong_gripper_2f85_fix_base_usda_M_arm_l_01"/>
        <motor ctrllimited="true" ctrlrange="-80 80" gear="1" joint="openloong_gripper_2f85_fix_base_usda_J_arm_l_02" name="openloong_gripper_2f85_fix_base_usda_M_arm_l_02"/>
        <motor ctrllimited="true" ctrlrange="-48 48" gear="1" joint="openloong_gripper_2f85_fix_base_usda_J_arm_l_03" name="openloong_gripper_2f85_fix_base_usda_M_arm_l_03"/>
        <motor ctrllimited="true" ctrlrange="-48 48" gear="1" joint="openloong_gripper_2f85_fix_base_usda_J_arm_l_04" name="openloong_gripper_2f85_fix_base_usda_M_arm_l_04"/>
        <motor ctrllimited="true" ctrlrange="-12.4 12.4" gear="1" joint="openloong_gripper_2f85_fix_base_usda_J_arm_l_05" name="openloong_gripper_2f85_fix_base_usda_M_arm_l_05"/>
        <motor ctrllimited="true" ctrlrange="-12.4 12.4" gear="1" joint="openloong_gripper_2f85_fix_base_usda_J_arm_l_06" name="openloong_gripper_2f85_fix_base_usda_M_arm_l_06"/>
        <motor ctrllimited="true" ctrlrange="-12.4 12.4" gear="1" joint="openloong_gripper_2f85_fix_base_usda_J_arm_l_07" name="openloong_gripper_2f85_fix_base_usda_M_arm_l_07"/>
        <position ctrllimited="true" ctrlrange="-2.96706 2.96706" forcelimited="true" forcerange="-80 80" joint="openloong_gripper_2f85_fix_base_usda_J_arm_r_01" kp="200" kv="20" name="openloong_gripper_2f85_fix_base_usda_P_arm_r_01"/>
        <position ctrllimited="true" ctrlrange="-1.8326 1.8326" forcelimited="true" forcerange="-80 80" joint="openloong_gripper_2f85_fix_base_usda_J_arm_r_02" kp="200" kv="20" name="openloong_gripper_2f85_fix_base_usda_P_arm_r_02"/>
        <position ctrllimited="true" ctrlrange="-2.96706 2.96706" forcelimited="true" forcerange="-48 48" joint="openloong_gripper_2f85_fix_base_usda_J_arm_r_03" kp="200" kv="20" name="openloong_gripper_2f85_fix_base_usda_P_arm_r_03"/>
        <position ctrllimited="true" ctrlrange="0 2.96706" forcelimited="true" forcerange="-48 48" joint="openloong_gripper_2f85_fix_base_usda_J_arm_r_04" kp="200" kv="20" name="openloong_gripper_2f85_fix_base_usda_P_arm_r_04"/>
        <position ctrllimited="true" ctrlrange="-2.96706 2.96706" forcelimited="true" forcerange="-12.4 12.4" joint="openloong_gripper_2f85_fix_base_usda_J_arm_r_05" kp="200" kv="20" name="openloong_gripper_2f85_fix_base_usda_P_arm_r_05"/>
        <position ctrllimited="true" ctrlrange="-1.8326 1.8326" forcelimited="true" forcerange="-12.4 12.4" joint="openloong_gripper_2f85_fix_base_usda_J_arm_r_06" kp="200" kv="20" name="openloong_gripper_2f85_fix_base_usda_P_arm_r_06"/>
        <position ctrllimited="true" ctrlrange="-1.0472 1.0472" forcelimited="true" forcerange="-12.4 12.4" joint="openloong_gripper_2f85_fix_base_usda_J_arm_r_07" kp="200" kv="20" name="openloong_gripper_2f85_fix_base_usda_P_arm_r_07"/>
        <motor ctrllimited="true" ctrlrange="-80 80" gear="1" joint="openloong_gripper_2f85_fix_base_usda_J_arm_r_01" name="openloong_gripper_2f85_fix_base_usda_M_arm_r_01"/>
        <motor ctrllimited="true" ctrlrange="-80 80" gear="1" joint="openloong_gripper_2f85_fix_base_usda_J_arm_r_02" name="openloong_gripper_2f85_fix_base_usda_M_arm_r_02"/>
        <motor ctrllimited="true" ctrlrange="-48 48" gear="1" joint="openloong_gripper_2f85_fix_base_usda_J_arm_r_03" name="openloong_gripper_2f85_fix_base_usda_M_arm_r_03"/>
        <motor ctrllimited="true" ctrlrange="-48 48" gear="1" joint="openloong_gripper_2f85_fix_base_usda_J_arm_r_04" name="openloong_gripper_2f85_fix_base_usda_M_arm_r_04"/>
        <motor ctrllimited="true" ctrlrange="-12.4 12.4" gear="1" joint="openloong_gripper_2f85_fix_base_usda_J_arm_r_05" name="openloong_gripper_2f85_fix_base_usda_M_arm_r_05"/>
        <motor ctrllimited="true" ctrlrange="-12.4 12.4" gear="1" joint="openloong_gripper_2f85_fix_base_usda_J_arm_r_06" name="openloong_gripper_2f85_fix_base_usda_M_arm_r_06"/>
        <motor ctrllimited="true" ctrlrange="-12.4 12.4" gear="1" joint="openloong_gripper_2f85_fix_base_usda_J_arm_r_07" name="openloong_gripper_2f85_fix_base_usda_M_arm_r_07"/>
        <general biasprm="0 -100 -10" biastype="affine" ctrlrange="0 255" forcerange="-5 5" gainprm="0.3137255 0 0" name="openloong_gripper_2f85_fix_base_usda_l_fingers_actuator" tendon="openloong_gripper_2f85_fix_base_usda_l_split"/>
        <general biasprm="0 -100 -10" biastype="affine" ctrlrange="0 255" forcerange="-5 5" gainprm="0.3137255 0 0" name="openloong_gripper_2f85_fix_base_usda_r_fingers_actuator" tendon="openloong_gripper_2f85_fix_base_usda_r_split"/>
    </actuator>
    <contact>
        <exclude body1="openloong_gripper_2f85_fix_base_usda_base_link" body2="openloong_gripper_2f85_fix_base_usda_Link_head_pitch"/>
        <exclude body1="openloong_gripper_2f85_fix_base_usda_base_link" body2="openloong_gripper_2f85_fix_base_usda_Link_arm_r_01"/>
        <exclude body1="openloong_gripper_2f85_fix_base_usda_base_link" body2="openloong_gripper_2f85_fix_base_usda_Link_head_yaw"/>
        <exclude body1="openloong_gripper_2f85_fix_base_usda_base_link" body2="openloong_gripper_2f85_fix_base_usda_Link_waist_pitch"/>
        <exclude body1="openloong_gripper_2f85_fix_base_usda_base_link" body2="openloong_gripper_2f85_fix_base_usda_Link_waist_roll"/>
        <exclude body1="openloong_gripper_2f85_fix_base_usda_base_link" body2="openloong_gripper_2f85_fix_base_usda_dummy_body"/>
        <exclude body1="openloong_gripper_2f85_fix_base_usda_base_link" body2="openloong_gripper_2f85_fix_base_usda_Link_arm_l_01"/>
        <exclude body1="openloong_gripper_2f85_fix_base_usda_Link_head_yaw" body2="openloong_gripper_2f85_fix_base_usda_Link_head_pitch"/>
        <exclude body1="openloong_gripper_2f85_fix_base_usda_Link_waist_pitch" body2="openloong_gripper_2f85_fix_base_usda_Link_waist_roll"/>
        <exclude body1="openloong_gripper_2f85_fix_base_usda_Link_waist_roll" body2="openloong_gripper_2f85_fix_base_usda_Link_waist_yaw"/>
        <exclude body1="openloong_gripper_2f85_fix_base_usda_Link_waist_yaw" body2="openloong_gripper_2f85_fix_base_usda_Link_hip_l_pitch"/>
        <exclude body1="openloong_gripper_2f85_fix_base_usda_Link_waist_yaw" body2="openloong_gripper_2f85_fix_base_usda_Link_hip_r_yaw"/>
        <exclude body1="openloong_gripper_2f85_fix_base_usda_Link_waist_yaw" body2="openloong_gripper_2f85_fix_base_usda_Link_hip_l_yaw"/>
        <exclude body1="openloong_gripper_2f85_fix_base_usda_Link_waist_yaw" body2="openloong_gripper_2f85_fix_base_usda_Link_hip_r_roll"/>
        <exclude body1="openloong_gripper_2f85_fix_base_usda_Link_waist_yaw" body2="openloong_gripper_2f85_fix_base_usda_Link_hip_l_roll"/>
        <exclude body1="openloong_gripper_2f85_fix_base_usda_Link_waist_yaw" body2="openloong_gripper_2f85_fix_base_usda_Link_hip_r_pitch"/>
        <exclude body1="openloong_gripper_2f85_fix_base_usda_Link_hip_r_roll" body2="openloong_gripper_2f85_fix_base_usda_Link_hip_r_yaw"/>
        <exclude body1="openloong_gripper_2f85_fix_base_usda_Link_hip_r_yaw" body2="openloong_gripper_2f85_fix_base_usda_Link_hip_r_pitch"/>
        <exclude body1="openloong_gripper_2f85_fix_base_usda_Link_hip_r_pitch" body2="openloong_gripper_2f85_fix_base_usda_Link_knee_r_pitch"/>
        <exclude body1="openloong_gripper_2f85_fix_base_usda_Link_knee_r_pitch" body2="openloong_gripper_2f85_fix_base_usda_Link_ankle_r_pitch"/>
        <exclude body1="openloong_gripper_2f85_fix_base_usda_Link_knee_r_pitch" body2="openloong_gripper_2f85_fix_base_usda_Link_ankle_r_roll"/>
        <exclude body1="openloong_gripper_2f85_fix_base_usda_Link_ankle_r_pitch" body2="openloong_gripper_2f85_fix_base_usda_Link_ankle_r_roll"/>
        <exclude body1="openloong_gripper_2f85_fix_base_usda_Link_hip_l_roll" body2="openloong_gripper_2f85_fix_base_usda_Link_hip_l_yaw"/>
        <exclude body1="openloong_gripper_2f85_fix_base_usda_Link_hip_l_yaw" body2="openloong_gripper_2f85_fix_base_usda_Link_hip_l_pitch"/>
        <exclude body1="openloong_gripper_2f85_fix_base_usda_Link_hip_l_pitch" body2="openloong_gripper_2f85_fix_base_usda_Link_knee_l_pitch"/>
        <exclude body1="openloong_gripper_2f85_fix_base_usda_Link_knee_l_pitch" body2="openloong_gripper_2f85_fix_base_usda_Link_ankle_l_pitch"/>
        <exclude body1="openloong_gripper_2f85_fix_base_usda_Link_knee_l_pitch" body2="openloong_gripper_2f85_fix_base_usda_Link_ankle_l_roll"/>
        <exclude body1="openloong_gripper_2f85_fix_base_usda_Link_ankle_l_pitch" body2="openloong_gripper_2f85_fix_base_usda_Link_ankle_l_roll"/>
        <exclude body1="openloong_gripper_2f85_fix_base_usda_Link_arm_r_01" body2="openloong_gripper_2f85_fix_base_usda_Link_arm_r_02"/>
        <exclude body1="openloong_gripper_2f85_fix_base_usda_Link_arm_r_02" body2="openloong_gripper_2f85_fix_base_usda_Link_arm_r_03"/>
        <exclude body1="openloong_gripper_2f85_fix_base_usda_Link_arm_r_03" body2="openloong_gripper_2f85_fix_base_usda_Link_arm_r_04"/>
        <exclude body1="openloong_gripper_2f85_fix_base_usda_Link_arm_r_04" body2="openloong_gripper_2f85_fix_base_usda_Link_arm_r_05"/>
        <exclude body1="openloong_gripper_2f85_fix_base_usda_Link_arm_r_05" body2="openloong_gripper_2f85_fix_base_usda_Link_arm_r_06"/>
        <exclude body1="openloong_gripper_2f85_fix_base_usda_Link_arm_r_05" body2="openloong_gripper_2f85_fix_base_usda_Link_arm_r_07"/>
        <exclude body1="openloong_gripper_2f85_fix_base_usda_Link_arm_r_06" body2="openloong_gripper_2f85_fix_base_usda_Link_arm_r_07"/>
        <exclude body1="openloong_gripper_2f85_fix_base_usda_zbr_base_link" body2="openloong_gripper_2f85_fix_base_usda_r_right_spring_link"/>
        <exclude body1="openloong_gripper_2f85_fix_base_usda_zbr_base_link" body2="openloong_gripper_2f85_fix_base_usda_r_right_driver"/>
        <exclude body1="openloong_gripper_2f85_fix_base_usda_zbr_base_link" body2="openloong_gripper_2f85_fix_base_usda_r_left_driver"/>
        <exclude body1="openloong_gripper_2f85_fix_base_usda_zbr_base_link" body2="openloong_gripper_2f85_fix_base_usda_r_left_spring_link"/>
        <exclude body1="openloong_gripper_2f85_fix_base_usda_r_left_coupler" body2="openloong_gripper_2f85_fix_base_usda_r_left_follower"/>
        <exclude body1="openloong_gripper_2f85_fix_base_usda_r_right_coupler" body2="openloong_gripper_2f85_fix_base_usda_r_right_follower"/>
        <exclude body1="openloong_gripper_2f85_fix_base_usda_Link_arm_l_01" body2="openloong_gripper_2f85_fix_base_usda_Link_arm_l_02"/>
        <exclude body1="openloong_gripper_2f85_fix_base_usda_Link_arm_l_02" body2="openloong_gripper_2f85_fix_base_usda_Link_arm_l_03"/>
        <exclude body1="openloong_gripper_2f85_fix_base_usda_Link_arm_l_03" body2="openloong_gripper_2f85_fix_base_usda_Link_arm_l_04"/>
        <exclude body1="openloong_gripper_2f85_fix_base_usda_Link_arm_l_04" body2="openloong_gripper_2f85_fix_base_usda_Link_arm_l_05"/>
        <exclude body1="openloong_gripper_2f85_fix_base_usda_Link_arm_l_05" body2="openloong_gripper_2f85_fix_base_usda_Link_arm_l_07"/>
        <exclude body1="openloong_gripper_2f85_fix_base_usda_Link_arm_l_05" body2="openloong_gripper_2f85_fix_base_usda_Link_arm_l_06"/>
        <exclude body1="openloong_gripper_2f85_fix_base_usda_Link_arm_l_06" body2="openloong_gripper_2f85_fix_base_usda_Link_arm_l_07"/>
        <exclude body1="openloong_gripper_2f85_fix_base_usda_zbll_base_link" body2="openloong_gripper_2f85_fix_base_usda_l_left_driver"/>
        <exclude body1="openloong_gripper_2f85_fix_base_usda_zbll_base_link" body2="openloong_gripper_2f85_fix_base_usda_l_right_spring_link"/>
        <exclude body1="openloong_gripper_2f85_fix_base_usda_zbll_base_link" body2="openloong_gripper_2f85_fix_base_usda_l_left_spring_link"/>
        <exclude body1="openloong_gripper_2f85_fix_base_usda_zbll_base_link" body2="openloong_gripper_2f85_fix_base_usda_l_right_driver"/>
        <exclude body1="openloong_gripper_2f85_fix_base_usda_l_left_coupler" body2="openloong_gripper_2f85_fix_base_usda_l_left_follower"/>
        <exclude body1="openloong_gripper_2f85_fix_base_usda_l_right_coupler" body2="openloong_gripper_2f85_fix_base_usda_l_right_follower"/>
    </contact>
    <sensor>
        <framequat name="openloong_gripper_2f85_fix_base_usda_baselink-quat" objname="openloong_gripper_2f85_fix_base_usda_imu" objtype="site"/>
        <velocimeter name="openloong_gripper_2f85_fix_base_usda_baselink-velocity" site="openloong_gripper_2f85_fix_base_usda_imu"/>
        <gyro name="openloong_gripper_2f85_fix_base_usda_baselink-gyro" site="openloong_gripper_2f85_fix_base_usda_imu"/>
        <accelerometer name="openloong_gripper_2f85_fix_base_usda_baselink-baseAcc" site="openloong_gripper_2f85_fix_base_usda_imu"/>
        <touch name="openloong_gripper_2f85_fix_base_usda_lf-touch" site="openloong_gripper_2f85_fix_base_usda_lf-tc"/>
        <touch name="openloong_gripper_2f85_fix_base_usda_rf-touch" site="openloong_gripper_2f85_fix_base_usda_rf-tc"/>
    </sensor>
    <equality>
        <connect anchor="-0.0179014 -0.00651468 0.0044" body1="openloong_gripper_2f85_fix_base_usda_l_right_follower" body2="openloong_gripper_2f85_fix_base_usda_l_right_coupler" solimp="0.95 0.99 0.001" solref="0.005 1"/>
        <connect anchor="-0.0179014 -0.00651468 0.0044" body1="openloong_gripper_2f85_fix_base_usda_l_left_follower" body2="openloong_gripper_2f85_fix_base_usda_l_left_coupler" solimp="0.95 0.99 0.001" solref="0.005 1"/>
        <joint joint1="openloong_gripper_2f85_fix_base_usda_l_right_driver_joint" joint2="openloong_gripper_2f85_fix_base_usda_l_left_driver_joint" polycoef="0 1 0 0 0" solimp="0.95 0.99 0.001" solref="0.005 1"/>
        <connect anchor="-0.0179014 -0.00651468 0.0044" body1="openloong_gripper_2f85_fix_base_usda_r_right_follower" body2="openloong_gripper_2f85_fix_base_usda_r_right_coupler" solimp="0.95 0.99 0.001" solref="0.005 1"/>
        <connect anchor="-0.0179014 -0.00651468 0.0044" body1="openloong_gripper_2f85_fix_base_usda_r_left_follower" body2="openloong_gripper_2f85_fix_base_usda_r_left_coupler" solimp="0.95 0.99 0.001" solref="0.005 1"/>
        <joint joint1="openloong_gripper_2f85_fix_base_usda_r_right_driver_joint" joint2="openloong_gripper_2f85_fix_base_usda_r_left_driver_joint" polycoef="0 1 0 0 0" solimp="0.95 0.99 0.001" solref="0.005 1"/>
    </equality>
    <asset>
        <mesh name="Link_ankle_l_pitch" file="Link_ankle_l_pitch_67093450e7f254e1934ac7da4f43f17c.STL" scale="1.000000000 1.000000000 1.000000000"/>
        <mesh name="Link_ankle_r_pitch" file="Link_ankle_r_pitch_760d7edad15a80352870402d691885e5.STL" scale="1.000000000 1.000000000 1.000000000"/>
        <mesh name="Link_arm_l_01" file="Link_arm_l_01_4f62997b6241bc5ecbb615e6162a54a5.STL" scale="1.000000000 1.000000000 1.000000000"/>
        <mesh name="Link_arm_l_02" file="Link_arm_l_02_4f5a4d8b8283c7e788d5b3b6b5bcd2a0.STL" scale="1.000000000 1.000000000 1.000000000"/>
        <mesh name="Link_arm_l_03" file="Link_arm_l_03_e929cde29f58f906b30207b512276e44.STL" scale="1.000000000 1.000000000 1.000000000"/>
        <mesh name="Link_arm_l_04" file="Link_arm_l_04_0e030793c863ef100f8b16ff753ddea7.STL" scale="1.000000000 1.000000000 1.000000000"/>
        <mesh name="Link_arm_l_05" file="Link_arm_l_05_7a68518c392d6f9f309dc95a095f9f83.STL" scale="1.000000000 1.000000000 1.000000000"/>
        <mesh name="Link_arm_l_06" file="Link_arm_l_06_22f42bc1c06bf500250579846851a422.STL" scale="1.000000000 1.000000000 1.000000000"/>
        <mesh name="Link_arm_l_07" file="Link_arm_l_base_07_e481f83f7cee9597dacecc4fdce19008.STL" scale="1.000000000 1.000000000 1.000000000"/>
        <mesh name="Link_arm_r_01" file="Link_arm_r_01_ba840789e633b133b08695e217590c33.STL" scale="1.000000000 1.000000000 1.000000000"/>
        <mesh name="Link_arm_r_02" file="Link_arm_r_02_f34b371601d253b47c337455e2b378bb.STL" scale="1.000000000 1.000000000 1.000000000"/>
        <mesh name="Link_arm_r_03" file="Link_arm_r_03_3a227e23e333d1c4a9ac55bb66ccefbe.STL" scale="1.000000000 1.000000000 1.000000000"/>
        <mesh name="Link_arm_r_04" file="Link_arm_r_04_8cd4cb0ef16559d3d52c759391df6ed2.STL" scale="1.000000000 1.000000000 1.000000000"/>
        <mesh name="Link_arm_r_05" file="Link_arm_r_05_f1b7b3904cf9d88fb456b2367973e75b.STL" scale="1.000000000 1.000000000 1.000000000"/>
        <mesh name="Link_arm_r_06" file="Link_arm_r_06_449c2b48e33be153fa56c523f349023b.STL" scale="1.000000000 1.000000000 1.000000000"/>
        <mesh name="Link_arm_r_07" file="Link_arm_r_base_07_d3d167df6d26ee658e4451d170e614a7.STL" scale="1.000000000 1.000000000 1.000000000"/>
        <mesh name="Link_head_pitch" file="Link_head_pitch_c972fd0955a85702875a961871e480fe.STL" scale="1.000000000 1.000000000 1.000000000"/>
        <mesh name="Link_head_yaw" file="Link_head_yaw_2dd60c5d8ea974f35c723ead34bc5c0b.STL" scale="1.000000000 1.000000000 1.000000000"/>
        <mesh name="Link_hip_l_pitch" file="Link_hip_l_pitch_713ae281c9732ab61cc2c93e687d106c.STL" scale="1.000000000 1.000000000 1.000000000"/>
        <mesh name="Link_hip_l_roll" file="Link_hip_l_roll_06b505b11131c5b9754a7eb0b5f3c8b1.STL" scale="1.000000000 1.000000000 1.000000000"/>
        <mesh name="Link_hip_l_yaw" file="Link_hip_l_yaw_c01ac9ad217f6fb06c88105836593329.STL" scale="1.000000000 1.000000000 1.000000000"/>
        <mesh name="Link_hip_r_pitch" file="Link_hip_r_pitch_49e80d7f147768f038305a9b00f896b9.STL" scale="1.000000000 1.000000000 1.000000000"/>
        <mesh name="Link_hip_r_roll" file="Link_hip_r_roll_de237e72f62396ccd728e031259f10f7.STL" scale="1.000000000 1.000000000 1.000000000"/>
        <mesh name="Link_hip_r_yaw" file="Link_hip_r_yaw_a23c304f89da078bbe9305324f79a38f.STL" scale="1.000000000 1.000000000 1.000000000"/>
        <mesh name="Link_knee_l_pitch" file="Link_knee_l_pitch_f057ed4ee70e503dd0fec505facbc61c.STL" scale="1.000000000 1.000000000 1.000000000"/>
        <mesh name="Link_knee_r_pitch" file="Link_knee_r_pitch_c35d505d926bf785ec473f5e10cc4e51.STL" scale="1.000000000 1.000000000 1.000000000"/>
        <mesh name="Link_waist_pitch" file="Link_waist_pitch_63e23c0d71e8d140a9ec7c20fd4f402a.STL" scale="1.000000000 1.000000000 1.000000000"/>
        <mesh name="Link_waist_roll" file="Link_waist_roll_493be1e5c0e0b67784629ebb8f649dde.STL" scale="1.000000000 1.000000000 1.000000000"/>
        <mesh name="Link_waist_yaw" file="Link_waist_yaw_969c24f424410d049de7520b95acbaae.STL" scale="1.000000000 1.000000000 1.000000000"/>
        <mesh name="base" file="base_6d026acc3f373d92ac18dbde923df313.stl" scale="1.000000000 1.000000000 1.000000000"/>
        <mesh name="base_link" file="base_link_6ab05a4098519d5d62c8f2abb4204786.STL" scale="1.000000000 1.000000000 1.000000000"/>
        <mesh name="coupler" file="coupler_246ee2cbc8ceda386deeb265f8872bc6.stl" scale="1.000000000 1.000000000 1.000000000"/>
        <mesh name="driver" file="driver_a80993b2d8497bbdcb58c5abe33d6bb0.stl" scale="1.000000000 1.000000000 1.000000000"/>
        <mesh name="follower" file="follower_26535b7e869bba4b70fc1348213ba31b.stl" scale="1.000000000 1.000000000 1.000000000"/>
        <mesh name="spring_link" file="spring_link_c2f397d7febe47b02ae1461d07d3d055.stl" scale="1.000000000 1.000000000 1.000000000"/>
        <mesh name="tongue" file="tongue_0d6b81a89c130c1b8295fe8834341042.stl" scale="1.000000000 1.000000000 1.000000000"/>
    </asset>
</mujoco>
