<mujoco model="rm_65_with_gripper">
  <compiler angle="radian"/>
  <asset>
    <mesh name="base_link" file="base_link.STL"/>
    <mesh name="link1" file="link1.STL"/>
    <mesh name="link2" file="link2.STL"/>
    <mesh name="link3" file="link3.STL"/>
    <mesh name="link4" file="link4.STL"/>
    <mesh name="link5" file="link5.STL"/>
    <mesh name="link6" file="link6.STL"/>
    <mesh name="Gripper_base_link" file="Gripper_base_link.STL"/>
    <mesh name="Gripper_Link1" file="Gripper_Link1.STL"/>
    <mesh name="Gripper_Link11" file="Gripper_Link11.STL"/>
    <mesh name="Gripper_Link2" file="Gripper_Link2.STL"/>
    <mesh name="Gripper_Link22" file="Gripper_Link22.STL"/>   
    <mesh name="base_link_coll" file="base_link_coll.stl"/>
    <mesh name="link1_coll" file="link1_coll.stl"/>
    <mesh name="link2_coll" file="link2_coll.stl"/>
    <mesh name="link3_coll" file="link3_coll.stl"/>
    <mesh name="link4_coll" file="link4_coll.stl"/>
    <mesh name="link5_coll" file="link5_coll.stl"/>
    <mesh name="link6_coll" file="link6_coll.stl"/>
    <mesh name="Gripper_base_link_coll" file="Gripper_base_link_coll.stl"/>
    <mesh name="Gripper_Link1_coll" file="Gripper_Link1_coll.stl"/>
    <mesh name="Gripper_Link11_coll" file="Gripper_Link11_coll.stl"/>
    <mesh name="Gripper_Link2_coll" file="Gripper_Link2_coll.stl"/>
    <mesh name="Gripper_Link22_coll" file="Gripper_Link22_coll.stl"/>   
  </asset>

  <default>
    <default class="visual">
      <geom type="mesh" contype="0" conaffinity="0" group="2"/>
    </default>
    <default class="collision">
      <geom type="mesh" group="3"/>
    </default>
  </default>

  <worldbody>
    <body mocap="true" name="ee_mocap" pos="-0.6000 0 0.4000">
        <geom conaffinity="0" contype="0" pos="0 0 0" rgba="0 0.5 0 0.7" size="0.005 0.005 0.005" type="box"></geom>
        <geom conaffinity="0" contype="0" pos="0 0 0" rgba="0 0.5 0 0.1" size="0.5 0.005 0.005" type="box"></geom>
        <geom conaffinity="0" contype="0" pos="0 0 0" rgba="0 0.5 0 0.1" size="0.005 0.5 0.001" type="box"></geom>
        <geom conaffinity="0" contype="0" pos="0 0 0" rgba="0 0.5 0 0.1" size="0.005 0.005 0.5" type="box"></geom>
    </body>

    <body name="base_link" pos="0 0 0">
      <geom type="mesh" rgba="1 1 1 1"  mesh="base_link" class="visual"/>
      <geom type="mesh" rgba="1 1 1 1"  mesh="base_link_coll" class="collision"/>
      <body name="Link1" pos="0 0 0.2405">
        <inertial pos="1.22263e-08 0.021108 -0.0251854" quat="0.988851 -0.148906 -2.80074e-05 -0.000243475" mass="0.593563" diaginertia="0.00126614 0.00124677 0.000496264"/>
        <joint name="joint1" pos="0 0 0" axis="0 0 1" limited="true" range="-3.1 3.1" damping="1"/>
        <geom type="mesh" rgba="1 1 1 1"  mesh="link1" class="visual"/>
        <geom type="mesh" rgba="1 1 1 1"  mesh="link1_coll" class="collision"/>
        <body name="Link2" quat="0.499998 0.5 -0.5 0.500002">
          <inertial pos="0.152256 4.75384e-07 -0.0062026" quat="1.2834e-05 0.785787 1.90512e-05 0.618497" mass="0.864175" diaginertia="0.00735632 0.00733754 0.000513875"/>
          <joint name="joint2" pos="0 0 0" axis="0 0 1" limited="true" range="-2.268 2.268" damping="1"/>
          <geom type="mesh" rgba="1 1 1 1"  mesh="link2" class="visual"/>
          <geom type="mesh" rgba="1 1 1 1"  mesh="link2_coll" class="collision"/>
          <body name="Link3" pos="0.256 0 0" quat="0.707105 0 0 0.707108">
            <inertial pos="5.05313e-06 -0.0595926 0.0105691" quat="0.424678 0.56496 -0.565554 0.424992" mass="0.289634" diaginertia="0.00065604 0.000637371 0.000114622"/>
            <joint name="joint3" pos="0 0 0" axis="0 0 1" limited="true" range="-2.355 2.355"  damping="1"/>
            <geom type="mesh" rgba="1 1 1 1"  mesh="link3" class="visual"/>
            <geom type="mesh" rgba="1 1 1 1"  mesh="link3_coll" class="collision"/>
            <body name="Link4" pos="0 -0.21 0" quat="0.707105 0.707108 0 0">
              <inertial pos="1.15517e-06 -0.0180424 -0.0215395" quat="0.990405 0.138195 -7.01319e-06 0.000110532" mass="0.23942" diaginertia="0.000285939 0.000275318 0.000107298"/>
              <joint name="joint4" pos="0 0 0" axis="0 0 1" limited="true" range="-3.1 3.1"  damping="1"/>
              <geom type="mesh" rgba="1 1 1 1"  mesh="link4" class="visual"/>
              <geom type="mesh" rgba="1 1 1 1"  mesh="link4_coll" class="collision"/>
              <body name="Link5" quat="0.707105 -0.707108 0 0">
                <inertial pos="3.19795e-06 -0.0593808 0.00736804" quat="0.419765 0.568659 -0.5692 0.420041" mass="0.2188" diaginertia="0.000358615 0.00035054 8.07958e-05"/>
                <joint name="joint5" pos="0 0 0" axis="0 0 1" limited="true" range="-2.233 2.233"  damping="1"/>
                <geom type="mesh" rgba="1 1 1 1"  mesh="link5" class="visual"/>
                <geom type="mesh" rgba="1 1 1 1"  mesh="link5_coll" class="collision"/>
                <body name="Link6" pos="0 -0.144 0" quat="0.707105 0.707108 0 0">
                  <inertial pos="0.000714235 -0.000396719 -0.0126724" quat="0.613063 0.350717 -0.614301 0.351831" mass="0.0649018" diaginertia="3.17886e-05 2.10548e-05 1.80205e-05"/>
                  <joint name="joint6" pos="0 0 0" axis="0 0 1" limited="true" range="-6.28 6.28" damping="1"/>
                  <geom type="mesh" rgba="1 1 1 1"  mesh="link6" class="visual"/>
                  <geom type="mesh" rgba="1 1 1 1"  mesh="link6_coll" class="collision"/>
                  <body name="Gripper_base_link" pos="-0.009652004 -0.000000060 0.042412579" quat="0.707105 0 -0.707108 0">
                    <geom type="mesh" rgba="0.894118 0.913725 0.929412 1"  mesh="Gripper_base_link" class="visual"/>
                    <geom type="mesh" rgba="0.894118 0.913725 0.929412 1"  mesh="Gripper_base_link_coll" class="collision"/>
                    <body pos="0.1000 0.000000000 -0.011360586" name="ee_center_body">
                        <site size="0.010000000 0.005000000 0.005000000" rgba="0.500000000 0.500000000 0.500000000 1.000000000" pos="0.000000000 0.000000000 0.000000000" quat="1.000000000 0.000000000 0.000000000 0.000000000" group="0" type="sphere" name="ee_center_site"/>
                    </body>            
                    <body name="Gripper_Link1" pos="0.036 -0.04 -0.019" quat="0.988227 0 0 -0.152992">
                      <inertial pos="0.016415 9.75755e-09 0.00898194" quat="0.500415 0.499584 0.499584 0.500415" mass="0.00647716" diaginertia="1.6998e-06 1.45017e-06 2.95066e-07"/>
                      <joint name="Gripper_Link1" pos="0 0 0" axis="0 0 1" limited="true" range="0 1"  damping="0.2" stiffness="0"/>
                      <geom type="mesh" rgba="0.894118 0.913725 0.929412 1"  mesh="Gripper_Link1" class="visual"/>
                      <geom type="mesh" rgba="0.894118 0.913725 0.929412 1"  mesh="Gripper_Link1_coll" class="collision"/>
                      <body name="Gripper_Link11" pos="0.042 0 0.003" quat="0.988227 0 0 0.152992">
                        <inertial pos="0.0113666 0.0118643 0.00600001" quat="0.427363 0.427363 0.563348 0.563348" mass="0.0127543" diaginertia="1.52644e-06 1.50565e-06 4.93551e-07"/>
                        <joint name="Gripper_Link11" pos="0 0 0" axis="0 0 1" limited="true" range="-1 0"  damping="0.2" stiffness="1"/>
                        <geom type="mesh" rgba="0.894118 0.913725 0.929412 1"  mesh="Gripper_Link11" class="visual"/>
                        <geom type="mesh" rgba="0.894118 0.913725 0.929412 1"  mesh="Gripper_Link11_coll" class="collision"/>
                      </body>
                    </body>
                    <body name="Gripper_Link2" pos="0.036 0.04 -0.019" quat="0.988227 0 0 0.152992">
                      <inertial pos="0.016415 9.75755e-09 0.00898194" quat="0.500415 0.499584 0.499584 0.500415" mass="0.00647716" diaginertia="1.6998e-06 1.45017e-06 2.95066e-07"/>
                      <joint name="Gripper_Link2" pos="0 0 0" axis="0 0 1" limited="true" range="-1 0"  damping="0.2" stiffness="0"/>
                      <geom type="mesh" rgba="0.894118 0.913725 0.929412 1"  mesh="Gripper_Link2" class="visual"/>
                      <geom type="mesh" rgba="0.894118 0.913725 0.929412 1"  mesh="Gripper_Link2_coll" class="collision"/>
                      <body name="Gripper_Link22" pos="0.042 0 0.015" quat="0.152993 0 0 0.988227">
                        <inertial pos="-0.0113666 0.0118643 -0.00600001" quat="0.563348 0.563348 0.427363 0.427363" mass="0.0127543" diaginertia="1.52644e-06 1.50565e-06 4.93551e-07"/>
                        <joint name="Gripper_Link22" pos="0 0 0" axis="0 0 1" limited="true" range="0 1"  damping="0.2" stiffness="1"/>
                        <geom type="mesh" rgba="0.894118 0.913725 0.929412 1"  mesh="Gripper_Link22" class="visual"/>
                        <geom type="mesh" rgba="0.894118 0.913725 0.929412 1"  mesh="Gripper_Link22_coll" class="collision"/>
                      </body>
                    </body>
                  </body>
                </body>
              </body>
            </body>
          </body>
        </body>
      </body>
    </body>
  </worldbody>

  <actuator>
    <motor name="actuator1" joint="joint1" gear="100" ctrllimited="true" ctrlrange="-80 80"/>
    <motor name="actuator2" joint="joint2" gear="1" ctrllimited="true" ctrlrange="-80 80"/>
    <motor name="actuator3" joint="joint3" gear="1" ctrllimited="true" ctrlrange="-48 48"/>
    <motor name="actuator4" joint="joint4" gear="1" ctrllimited="true" ctrlrange="-48 48"/>
    <motor name="actuator5" joint="joint5" gear="1" ctrllimited="true" ctrlrange="-12.4 12.4"/>
    <motor name="actuator6" joint="joint6" gear="100" ctrllimited="true" ctrlrange="-12.4 12.4"/>

    <position name="actuator_gripper1" joint="Gripper_Link1" ctrlrange="0 0.6981" forcerange="-15 15" />
    <position name="actuator_gripper2" joint="Gripper_Link2" ctrlrange="-0.6981 0" forcerange="-15 15" />
    <position name="actuator_gripper11" joint="Gripper_Link11" ctrlrange="-0.6981 0" forcerange="-15 15" />
    <position name="actuator_gripper22" joint="Gripper_Link22" ctrlrange="-0.6981 0" forcerange="-15 15" />
  </actuator>  
</mujoco>